Workbook
Name ch1_cats: OFFSET(Calc_Charts!$A$66,0,0,MAX(1,COUNTIF(Calc_Charts!$B$66:$B$90,">0")),1)
Name ch1_seg01: OFFSET(Calc_Charts!$C$66,0,0,MAX(1,COUNTIF(Calc_Charts!$B$66:$B$90,">0")),1)
Name ch1_seg02: OFFSET(Calc_Charts!$D$66,0,0,MAX(1,COUNTIF(Calc_Charts!$B$66:$B$90,">0")),1)
Name ch1_seg03: OFFSET(Calc_Charts!$E$66,0,0,MAX(1,COUNTIF(Calc_Charts!$B$66:$B$90,">0")),1)
Name ch1_seg04: OFFSET(Calc_Charts!$F$66,0,0,MAX(1,COUNTIF(Calc_Charts!$B$66:$B$90,">0")),1)
Name ch1_seg05: OFFSET(Calc_Charts!$G$66,0,0,MAX(1,COUNTIF(Calc_Charts!$B$66:$B$90,">0")),1)
Name ch1_seg06: OFFSET(Calc_Charts!$H$66,0,0,MAX(1,COUNTIF(Calc_Charts!$B$66:$B$90,">0")),1)
Name ch1_seg07: OFFSET(Calc_Charts!$I$66,0,0,MAX(1,COUNTIF(Calc_Charts!$B$66:$B$90,">0")),1)
Name ch1_seg08: OFFSET(Calc_Charts!$J$66,0,0,MAX(1,COUNTIF(Calc_Charts!$B$66:$B$90,">0")),1)
Name ch1_seg09: OFFSET(Calc_Charts!$K$66,0,0,MAX(1,COUNTIF(Calc_Charts!$B$66:$B$90,">0")),1)
Name ch1_seg10: OFFSET(Calc_Charts!$L$66,0,0,MAX(1,COUNTIF(Calc_Charts!$B$66:$B$90,">0")),1)
Name ch1_seg11: OFFSET(Calc_Charts!$M$66,0,0,MAX(1,COUNTIF(Calc_Charts!$B$66:$B$90,">0")),1)
Name ch1_seg12: OFFSET(Calc_Charts!$N$66,0,0,MAX(1,COUNTIF(Calc_Charts!$B$66:$B$90,">0")),1)
Name ch1_seg13: OFFSET(Calc_Charts!$O$66,0,0,MAX(1,COUNTIF(Calc_Charts!$B$66:$B$90,">0")),1)
Name ch1_seg14: OFFSET(Calc_Charts!$P$66,0,0,MAX(1,COUNTIF(Calc_Charts!$B$66:$B$90,">0")),1)
Name ch1_seg15: OFFSET(Calc_Charts!$Q$66,0,0,MAX(1,COUNTIF(Calc_Charts!$B$66:$B$90,">0")),1)
Name ch1_seg16: OFFSET(Calc_Charts!$R$66,0,0,MAX(1,COUNTIF(Calc_Charts!$B$66:$B$90,">0")),1)
Name ch1_seg17: OFFSET(Calc_Charts!$S$66,0,0,MAX(1,COUNTIF(Calc_Charts!$B$66:$B$90,">0")),1)
Name ch1_seg18: OFFSET(Calc_Charts!$T$66,0,0,MAX(1,COUNTIF(Calc_Charts!$B$66:$B$90,">0")),1)
Name ch1_seg19: OFFSET(Calc_Charts!$U$66,0,0,MAX(1,COUNTIF(Calc_Charts!$B$66:$B$90,">0")),1)
Name ch1_seg20: OFFSET(Calc_Charts!$V$66,0,0,MAX(1,COUNTIF(Calc_Charts!$B$66:$B$90,">0")),1)
Name ch1_seg21: OFFSET(Calc_Charts!$W$66,0,0,MAX(1,COUNTIF(Calc_Charts!$B$66:$B$90,">0")),1)
Name ch1_seg22: OFFSET(Calc_Charts!$X$66,0,0,MAX(1,COUNTIF(Calc_Charts!$B$66:$B$90,">0")),1)
Name ch1_seg23: OFFSET(Calc_Charts!$Y$66,0,0,MAX(1,COUNTIF(Calc_Charts!$B$66:$B$90,">0")),1)
Name ch1_seg24: OFFSET(Calc_Charts!$Z$66,0,0,MAX(1,COUNTIF(Calc_Charts!$B$66:$B$90,">0")),1)
Name ch1_seg25: OFFSET(Calc_Charts!$AA$66,0,0,MAX(1,COUNTIF(Calc_Charts!$B$66:$B$90,">0")),1)
Name ch1_vals: OFFSET(Calc_Charts!$B$66,0,0,MAX(1,COUNTIF(Calc_Charts!$B$66:$B$90,">0")),1)
Name ch3_cats: OFFSET(Calc_Charts!$A$96,0,0,MAX(1,COUNTIF(Calc_Charts!$B$96:$B$120,">0")),1)
Name ch3_seg01: OFFSET(Calc_Charts!$C$96,0,0,MAX(1,COUNTIF(Calc_Charts!$B$96:$B$120,">0")),1)
Name ch3_seg02: OFFSET(Calc_Charts!$D$96,0,0,MAX(1,COUNTIF(Calc_Charts!$B$96:$B$120,">0")),1)
Name ch3_seg03: OFFSET(Calc_Charts!$E$96,0,0,MAX(1,COUNTIF(Calc_Charts!$B$96:$B$120,">0")),1)
Name ch3_seg04: OFFSET(Calc_Charts!$F$96,0,0,MAX(1,COUNTIF(Calc_Charts!$B$96:$B$120,">0")),1)
Name ch3_seg05: OFFSET(Calc_Charts!$G$96,0,0,MAX(1,COUNTIF(Calc_Charts!$B$96:$B$120,">0")),1)
Name ch3_seg06: OFFSET(Calc_Charts!$H$96,0,0,MAX(1,COUNTIF(Calc_Charts!$B$96:$B$120,">0")),1)
Name ch3_seg07: OFFSET(Calc_Charts!$I$96,0,0,MAX(1,COUNTIF(Calc_Charts!$B$96:$B$120,">0")),1)
Name ch3_seg08: OFFSET(Calc_Charts!$J$96,0,0,MAX(1,COUNTIF(Calc_Charts!$B$96:$B$120,">0")),1)
Name ch3_seg09: OFFSET(Calc_Charts!$K$96,0,0,MAX(1,COUNTIF(Calc_Charts!$B$96:$B$120,">0")),1)
Name ch3_seg10: OFFSET(Calc_Charts!$L$96,0,0,MAX(1,COUNTIF(Calc_Charts!$B$96:$B$120,">0")),1)
Name ch3_seg11: OFFSET(Calc_Charts!$M$96,0,0,MAX(1,COUNTIF(Calc_Charts!$B$96:$B$120,">0")),1)
Name ch3_seg12: OFFSET(Calc_Charts!$N$96,0,0,MAX(1,COUNTIF(Calc_Charts!$B$96:$B$120,">0")),1)
Name ch3_seg13: OFFSET(Calc_Charts!$O$96,0,0,MAX(1,COUNTIF(Calc_Charts!$B$96:$B$120,">0")),1)
Name ch3_seg14: OFFSET(Calc_Charts!$P$96,0,0,MAX(1,COUNTIF(Calc_Charts!$B$96:$B$120,">0")),1)
Name ch3_seg15: OFFSET(Calc_Charts!$Q$96,0,0,MAX(1,COUNTIF(Calc_Charts!$B$96:$B$120,">0")),1)
Name ch3_seg16: OFFSET(Calc_Charts!$R$96,0,0,MAX(1,COUNTIF(Calc_Charts!$B$96:$B$120,">0")),1)
Name ch3_seg17: OFFSET(Calc_Charts!$S$96,0,0,MAX(1,COUNTIF(Calc_Charts!$B$96:$B$120,">0")),1)
Name ch3_seg18: OFFSET(Calc_Charts!$T$96,0,0,MAX(1,COUNTIF(Calc_Charts!$B$96:$B$120,">0")),1)
Name ch3_seg19: OFFSET(Calc_Charts!$U$96,0,0,MAX(1,COUNTIF(Calc_Charts!$B$96:$B$120,">0")),1)
Name ch3_seg20: OFFSET(Calc_Charts!$V$96,0,0,MAX(1,COUNTIF(Calc_Charts!$B$96:$B$120,">0")),1)
Name ch3_seg21: OFFSET(Calc_Charts!$W$96,0,0,MAX(1,COUNTIF(Calc_Charts!$B$96:$B$120,">0")),1)
Name ch3_seg22: OFFSET(Calc_Charts!$X$96,0,0,MAX(1,COUNTIF(Calc_Charts!$B$96:$B$120,">0")),1)
Name ch3_seg23: OFFSET(Calc_Charts!$Y$96,0,0,MAX(1,COUNTIF(Calc_Charts!$B$96:$B$120,">0")),1)
Name ch3_seg24: OFFSET(Calc_Charts!$Z$96,0,0,MAX(1,COUNTIF(Calc_Charts!$B$96:$B$120,">0")),1)
Name ch3_seg25: OFFSET(Calc_Charts!$AA$96,0,0,MAX(1,COUNTIF(Calc_Charts!$B$96:$B$120,">0")),1)
Name ch3_vals: OFFSET(Calc_Charts!$B$96,0,0,MAX(1,COUNTIF(Calc_Charts!$B$96:$B$120,">0")),1)
Name ch5_after: OFFSET(Calc_Charts!$B$126,0,0,MAX(1,COUNTIF(Calc_Charts!$D$126:$D$150,">0")),1)
Name ch5_before: OFFSET(Calc_Charts!$C$126,0,0,MAX(1,COUNTIF(Calc_Charts!$D$126:$D$150,">0")),1)
Name ch5_cats: OFFSET(Calc_Charts!$A$126,0,0,MAX(1,COUNTIF(Calc_Charts!$D$126:$D$150,">0")),1)
Name ch5_seg01: OFFSET(Calc_Charts!$B$156,0,0,MAX(1,COUNTIF(Calc_Charts!$D$126:$D$150,">0")),1)
Name ch5_seg02: OFFSET(Calc_Charts!$C$156,0,0,MAX(1,COUNTIF(Calc_Charts!$D$126:$D$150,">0")),1)
Name ch5_seg03: OFFSET(Calc_Charts!$D$156,0,0,MAX(1,COUNTIF(Calc_Charts!$D$126:$D$150,">0")),1)

Sheet Dashboard
A1: DG Service-Call Dashboard Explore sheet: use slicers there for slice-and-dice; refresh pivot after new data.
A3: From | B3: 46174
A4: To | B4: 46218
A5: Period | B5: =Calc_Charts!$B$262 -> Jun 1 to Jul 15
A6: Checks needing review | B6: =COUNTIF('Data Checks'!C:C,"Review") -> 1
A124: Timeline - pick cause OR group:
A125: Timeline cause | B125: Communication problem
A126: Date basis | B126: Commission date

Sheet Explore
A1: Slice-and-dice. Slicers filter the chart and table live. Right-click Refresh after adding Summary rows.
A58: Row Labels | B58: Count of Work Order
A59: False Alarm | B59: 1
A60: Grand Total | B60: 1

Sheet Data Checks
A1: Check | B1: Count | C1: Status | D1: What to fix | E1: Formula scope
A2: Heatmap classified line reconciliation | B2: =SUM('Heatmap Calc'!$B$5:$T$30) -> 80 | C2: =IF(B2=SUMPRODUCT(--(Summary!$E$2:$E$240<>""),--ISNUMBER(MATCH(Summary!$E$2:$E$240,Settings!$A$4:$A$29,0)),--(Summary!$A$2:$A$240>=IF(Dashboard!$B$3="",0,Dashboard!$B$3)),--(Summary!$A$2:$A$240<IF(Dashboard!$B$4="",2958465,Dashboard!$B$4+1))),"OK","Review") -> OK | D2: Heatmap sum must equal classified Summary lines in the active Dashboard date window. | E2: Heatmap Calc vs Summary
A3: Root causes not in Settings | B3: =SUMPRODUCT(--(Summary!$E$2:$E$240<>""),--ISNA(MATCH(Summary!$E$2:$E$240,Settings!$A$4:$A$104,0))) -> 0 | C3: =IF(B3=0,"OK","Review") -> OK | D3: Pick a valid Root Cause from the dropdown. | E3: Summary vs Settings
A4: Clean-point daily chart reconciliation | B4: =SUM('Timeline Calc'!B8:B191) -> 4 | C4: =IF(B4=IF(ISNUMBER(MATCH(tl_cause,Settings!$B$4:$B$83,0)),COUNTIFS(Summary!$K$2:$K$240,tl_cause,Summary!$A$2:$A$240,">="&IF(Dashboard!$B$3="",0,Dashboard!$B$3),Summary!$A$2:$A$240,"<"&IF(Dashboard!$B$4="",2958465,Dashboard!$B$4+1)),COUNTIFS(Summary!$E$2:$E$240,tl_cause,Summary!$A$2:$A$240,">="&IF(Dashboard!$B$3="",0,Dashboard!$B$3),Summary!$A$2:$A$240,"<"&IF(Dashboard!$B$4="",2958465,Dashboard!$B$4+1))),"OK","Review") -> OK | D4: Timeline sum must equal selected cause/group rows in the Dashboard call-date window; basis only changes plotted dates. | E4: Timeline Calc vs Summary
A5: Explore pivot grand total reconciliation | B5: =GETPIVOTDATA("Work Order",Explore!$A$58) -> 1 | C5: =IF(B5=SUMPRODUCT(--(Summary!$E$2:$E$240<>"")),"OK","Review") -> Review | D5: Clear Explore slicers and refresh pivot if this shows Review. | E5: Explore Pivot vs Summary

Sheet Heatmap Calc
A1: Cause x week heatmap - source range for the linked picture on Dashboard. Format HERE, not on the picture.
A3: ="Issues by root cause x "&LOWER(hm_basis)&" week ("&Dashboard!$B$5&")" -> Issues by root cause x call date week (Jun 1 to Jul 15)
B4: =$B$41 -> 46174.419 | C4: =B4+7 -> 46181.419 | D4: =C4+7 -> 46188.419 | E4: =D4+7 -> 46195.419 | F4: =E4+7 -> 46202.419 | G4: =F4+7 -> 46209.419 | H4: =G4+7 -> 46216.419 | I4: =H4+7 -> 46223.419 | J4: =I4+7 -> 46230.419 | ... T4: =S4+7 -> 46300.419
A5: =IF(Settings!A4="","",Settings!A4) -> Ref. leak/ Low charge | B5: =IF($A5="","",IF(hm_basis="Call date",COUNTIFS(Summary!$E$2:$E$240,$A5,Summary!$A$2:$A$240,">="&B4,Summary!$A$2:$A$240,"<"&B4+7,Summary!$A$2:$A$240,">="&IF(Dashboard!$B$3="",0,Dashboard!$B$3),Summary!$A$2:$A$240,"<"&IF(Dashboard!$B$4="",2958465,Dashboard!$B$4+1)),COUNTIFS(Summary!$E$2:$E$240,$A5,Summary!$D$2:$D$240,">="&B4,Summary!$D$2:$D$240,"<"&B4+7,Summary!$A$2:$A$240,">="&IF(Dashboard!$B$3="",0,Dashboard!$B$3),Summary!$A$2:$A$240,"<"&IF(Dashboard!$B$4="",2958465,Dashboard!$B$4+1)))) -> 2 | C5: =IF($A5="","",IF(hm_basis="Call date",COUNTIFS(Summary!$E$2:$E$240,$A5,Summary!$A$2:$A$240,">="&C4,Summary!$A$2:$A$240,"<"&C4+7,Summary!$A$2:$A$240,">="&IF(Dashboard!$B$3="",0,Dashboard!$B$3),Summary!$A$2:$A$240,"<"&IF(Dashboard!$B$4="",2958465,Dashboard!$B$4+1)),COUNTIFS(Summary!$E$2:$E$240,$A5,Summary!$D$2:$D$240,">="&C4,Summary!$D$2:$D$240,"<"&C4+7,Summary!$A$2:$A$240,">="&IF(Dashboard!$B$3="",0,Dashboard!$B$3),Summary!$A$2:$A$240,"<"&IF(Dashboard!$B$4="",2958465,Dashboard!$B$4+1)))) -> 0 | D5: =IF($A5="","",IF(hm_basis="Call date",COUNTIFS(Summary!$E$2:$E$240,$A5,Summary!$A$2:$A$240,">="&D4,Summary!$A$2:$A$240,"<"&D4+7,Summary!$A$2:$A$240,">="&IF(Dashboard!$B$3="",0,Dashboard!$B$3),Summary!$A$2:$A$240,"<"&IF(Dashboard!$B$4="",2958465,Dashboard!$B$4+1)),COUNTIFS(Summary!$E$2:$E$240,$A5,Summary!$D$2:$D$240,">="&D4,Summary!$D$2:$D$240,"<"&D4+7,Summary!$A$2:$A$240,">="&IF(Dashboard!$B$3="",0,Dashboard!$B$3),Summary!$A$2:$A$240,"<"&IF(Dashboard!$B$4="",2958465,Dashboard!$B$4+1)))) -> 0 | E5: =IF($A5="","",IF(hm_basis="Call date",COUNTIFS(Summary!$E$2:$E$240,$A5,Summary!$A$2:$A$240,">="&E4,Summary!$A$2:$A$240,"<"&E4+7,Summary!$A$2:$A$240,">="&IF(Dashboard!$B$3="",0,Dashboard!$B$3),Summary!$A$2:$A$240,"<"&IF(Dashboard!$B$4="",2958465,Dashboard!$B$4+1)),COUNTIFS(Summary!$E$2:$E$240,$A5,Summary!$D$2:$D$240,">="&E4,Summary!$D$2:$D$240,"<"&E4+7,Summary!$A$2:$A$240,">="&IF(Dashboard!$B$3="",0,Dashboard!$B$3),Summary!$A$2:$A$240,"<"&IF(Dashboard!$B$4="",2958465,Dashboard!$B$4+1)))) -> 0 | F5: =IF($A5="","",IF(hm_basis="Call date",COUNTIFS(Summary!$E$2:$E$240,$A5,Summary!$A$2:$A$240,">="&F4,Summary!$A$2:$A$240,"<"&F4+7,Summary!$A$2:$A$240,">="&IF(Dashboard!$B$3="",0,Dashboard!$B$3),Summary!$A$2:$A$240,"<"&IF(Dashboard!$B$4="",2958465,Dashboard!$B$4+1)),COUNTIFS(Summary!$E$2:$E$240,$A5,Summary!$D$2:$D$240,">="&F4,Summary!$D$2:$D$240,"<"&F4+7,Summary!$A$2:$A$240,">="&IF(Dashboard!$B$3="",0,Dashboard!$B$3),Summary!$A$2:$A$240,"<"&IF(Dashboard!$B$4="",2958465,Dashboard!$B$4+1)))) -> 0 | G5: =IF($A5="","",IF(hm_basis="Call date",COUNTIFS(Summary!$E$2:$E$240,$A5,Summary!$A$2:$A$240,">="&G4,Summary!$A$2:$A$240,"<"&G4+7,Summary!$A$2:$A$240,">="&IF(Dashboard!$B$3="",0,Dashboard!$B$3),Summary!$A$2:$A$240,"<"&IF(Dashboard!$B$4="",2958465,Dashboard!$B$4+1)),COUNTIFS(Summary!$E$2:$E$240,$A5,Summary!$D$2:$D$240,">="&G4,Summary!$D$2:$D$240,"<"&G4+7,Summary!$A$2:$A$240,">="&IF(Dashboard!$B$3="",0,Dashboard!$B$3),Summary!$A$2:$A$240,"<"&IF(Dashboard!$B$4="",2958465,Dashboard!$B$4+1)))) -> 2 | H5: =IF($A5="","",IF(hm_basis="Call date",COUNTIFS(Summary!$E$2:$E$240,$A5,Summary!$A$2:$A$240,">="&H4,Summary!$A$2:$A$240,"<"&H4+7,Summary!$A$2:$A$240,">="&IF(Dashboard!$B$3="",0,Dashboard!$B$3),Summary!$A$2:$A$240,"<"&IF(Dashboard!$B$4="",2958465,Dashboard!$B$4+1)),COUNTIFS(Summary!$E$2:$E$240,$A5,Summary!$D$2:$D$240,">="&H4,Summary!$D$2:$D$240,"<"&H4+7,Summary!$A$2:$A$240,">="&IF(Dashboard!$B$3="",0,Dashboard!$B$3),Summary!$A$2:$A$240,"<"&IF(Dashboard!$B$4="",2958465,Dashboard!$B$4+1)))) -> 0 | I5: =IF($A5="","",IF(hm_basis="Call date",COUNTIFS(Summary!$E$2:$E$240,$A5,Summary!$A$2:$A$240,">="&I4,Summary!$A$2:$A$240,"<"&I4+7,Summary!$A$2:$A$240,">="&IF(Dashboard!$B$3="",0,Dashboard!$B$3),Summary!$A$2:$A$240,"<"&IF(Dashboard!$B$4="",2958465,Dashboard!$B$4+1)),COUNTIFS(Summary!$E$2:$E$240,$A5,Summary!$D$2:$D$240,">="&I4,Summary!$D$2:$D$240,"<"&I4+7,Summary!$A$2:$A$240,">="&IF(Dashboard!$B$3="",0,Dashboard!$B$3),Summary!$A$2:$A$240,"<"&IF(Dashboard!$B$4="",2958465,Dashboard!$B$4+1)))) -> 0 | ... T5: =IF($A5="","",IF(hm_basis="Call date",COUNTIFS(Summary!$E$2:$E$240,$A5,Summary!$A$2:$A$240,">="&T4,Summary!$A$2:$A$240,"<"&T4+7,Summary!$A$2:$A$240,">="&IF(Dashboard!$B$3="",0,Dashboard!$B$3),Summary!$A$2:$A$240,"<"&IF(Dashboard!$B$4="",2958465,Dashboard!$B$4+1)),COUNTIFS(Summary!$E$2:$E$240,$A5,Summary!$D$2:$D$240,">="&T4,Summary!$D$2:$D$240,"<"&T4+7,Summary!$A$2:$A$240,">="&IF(Dashboard!$B$3="",0,Dashboard!$B$3),Summary!$A$2:$A$240,"<"&IF(Dashboard!$B$4="",2958465,Dashboard!$B$4+1)))) -> 0
A6: =IF(Settings!A5="","",Settings!A5) -> Door Torque | B6: =IF($A6="","",IF(hm_basis="Call date",COUNTIFS(Summary!$E$2:$E$240,$A6,Summary!$A$2:$A$240,">="&B4,Summary!$A$2:$A$240,"<"&B4+7,Summary!$A$2:$A$240,">="&IF(Dashboard!$B$3="",0,Dashboard!$B$3),Summary!$A$2:$A$240,"<"&IF(Dashboard!$B$4="",2958465,Dashboard!$B$4+1)),COUNTIFS(Summary!$E$2:$E$240,$A6,Summary!$D$2:$D$240,">="&B4,Summary!$D$2:$D$240,"<"&B4+7,Summary!$A$2:$A$240,">="&IF(Dashboard!$B$3="",0,Dashboard!$B$3),Summary!$A$2:$A$240,"<"&IF(Dashboard!$B$4="",2958465,Dashboard!$B$4+1)))) -> 0 | C6: =IF($A6="","",IF(hm_basis="Call date",COUNTIFS(Summary!$E$2:$E$240,$A6,Summary!$A$2:$A$240,">="&C4,Summary!$A$2:$A$240,"<"&C4+7,Summary!$A$2:$A$240,">="&IF(Dashboard!$B$3="",0,Dashboard!$B$3),Summary!$A$2:$A$240,"<"&IF(Dashboard!$B$4="",2958465,Dashboard!$B$4+1)),COUNTIFS(Summary!$E$2:$E$240,$A6,Summary!$D$2:$D$240,">="&C4,Summary!$D$2:$D$240,"<"&C4+7,Summary!$A$2:$A$240,">="&IF(Dashboard!$B$3="",0,Dashboard!$B$3),Summary!$A$2:$A$240,"<"&IF(Dashboard!$B$4="",2958465,Dashboard!$B$4+1)))) -> 2 | D6: =IF($A6="","",IF(hm_basis="Call date",COUNTIFS(Summary!$E$2:$E$240,$A6,Summary!$A$2:$A$240,">="&D4,Summary!$A$2:$A$240,"<"&D4+7,Summary!$A$2:$A$240,">="&IF(Dashboard!$B$3="",0,Dashboard!$B$3),Summary!$A$2:$A$240,"<"&IF(Dashboard!$B$4="",2958465,Dashboard!$B$4+1)),COUNTIFS(Summary!$E$2:$E$240,$A6,Summary!$D$2:$D$240,">="&D4,Summary!$D$2:$D$240,"<"&D4+7,Summary!$A$2:$A$240,">="&IF(Dashboard!$B$3="",0,Dashboard!$B$3),Summary!$A$2:$A$240,"<"&IF(Dashboard!$B$4="",2958465,Dashboard!$B$4+1)))) -> 0 | E6: =IF($A6="","",IF(hm_basis="Call date",COUNTIFS(Summary!$E$2:$E$240,$A6,Summary!$A$2:$A$240,">="&E4,Summary!$A$2:$A$240,"<"&E4+7,Summary!$A$2:$A$240,">="&IF(Dashboard!$B$3="",0,Dashboard!$B$3),Summary!$A$2:$A$240,"<"&IF(Dashboard!$B$4="",2958465,Dashboard!$B$4+1)),COUNTIFS(Summary!$E$2:$E$240,$A6,Summary!$D$2:$D$240,">="&E4,Summary!$D$2:$D$240,"<"&E4+7,Summary!$A$2:$A$240,">="&IF(Dashboard!$B$3="",0,Dashboard!$B$3),Summary!$A$2:$A$240,"<"&IF(Dashboard!$B$4="",2958465,Dashboard!$B$4+1)))) -> 2 | F6: =IF($A6="","",IF(hm_basis="Call date",COUNTIFS(Summary!$E$2:$E$240,$A6,Summary!$A$2:$A$240,">="&F4,Summary!$A$2:$A$240,"<"&F4+7,Summary!$A$2:$A$240,">="&IF(Dashboard!$B$3="",0,Dashboard!$B$3),Summary!$A$2:$A$240,"<"&IF(Dashboard!$B$4="",2958465,Dashboard!$B$4+1)),COUNTIFS(Summary!$E$2:$E$240,$A6,Summary!$D$2:$D$240,">="&F4,Summary!$D$2:$D$240,"<"&F4+7,Summary!$A$2:$A$240,">="&IF(Dashboard!$B$3="",0,Dashboard!$B$3),Summary!$A$2:$A$240,"<"&IF(Dashboard!$B$4="",2958465,Dashboard!$B$4+1)))) -> 0 | G6: =IF($A6="","",IF(hm_basis="Call date",COUNTIFS(Summary!$E$2:$E$240,$A6,Summary!$A$2:$A$240,">="&G4,Summary!$A$2:$A$240,"<"&G4+7,Summary!$A$2:$A$240,">="&IF(Dashboard!$B$3="",0,Dashboard!$B$3),Summary!$A$2:$A$240,"<"&IF(Dashboard!$B$4="",2958465,Dashboard!$B$4+1)),COUNTIFS(Summary!$E$2:$E$240,$A6,Summary!$D$2:$D$240,">="&G4,Summary!$D$2:$D$240,"<"&G4+7,Summary!$A$2:$A$240,">="&IF(Dashboard!$B$3="",0,Dashboard!$B$3),Summary!$A$2:$A$240,"<"&IF(Dashboard!$B$4="",2958465,Dashboard!$B$4+1)))) -> 3 | H6: =IF($A6="","",IF(hm_basis="Call date",COUNTIFS(Summary!$E$2:$E$240,$A6,Summary!$A$2:$A$240,">="&H4,Summary!$A$2:$A$240,"<"&H4+7,Summary!$A$2:$A$240,">="&IF(Dashboard!$B$3="",0,Dashboard!$B$3),Summary!$A$2:$A$240,"<"&IF(Dashboard!$B$4="",2958465,Dashboard!$B$4+1)),COUNTIFS(Summary!$E$2:$E$240,$A6,Summary!$D$2:$D$240,">="&H4,Summary!$D$2:$D$240,"<"&H4+7,Summary!$A$2:$A$240,">="&IF(Dashboard!$B$3="",0,Dashboard!$B$3),Summary!$A$2:$A$240,"<"&IF(Dashboard!$B$4="",2958465,Dashboard!$B$4+1)))) -> 0 | I6: =IF($A6="","",IF(hm_basis="Call date",COUNTIFS(Summary!$E$2:$E$240,$A6,Summary!$A$2:$A$240,">="&I4,Summary!$A$2:$A$240,"<"&I4+7,Summary!$A$2:$A$240,">="&IF(Dashboard!$B$3="",0,Dashboard!$B$3),Summary!$A$2:$A$240,"<"&IF(Dashboard!$B$4="",2958465,Dashboard!$B$4+1)),COUNTIFS(Summary!$E$2:$E$240,$A6,Summary!$D$2:$D$240,">="&I4,Summary!$D$2:$D$240,"<"&I4+7,Summary!$A$2:$A$240,">="&IF(Dashboard!$B$3="",0,Dashboard!$B$3),Summary!$A$2:$A$240,"<"&IF(Dashboard!$B$4="",2958465,Dashboard!$B$4+1)))) -> 0 | ... T6: =IF($A6="","",IF(hm_basis="Call date",COUNTIFS(Summary!$E$2:$E$240,$A6,Summary!$A$2:$A$240,">="&T4,Summary!$A$2:$A$240,"<"&T4+7,Summary!$A$2:$A$240,">="&IF(Dashboard!$B$3="",0,Dashboard!$B$3),Summary!$A$2:$A$240,"<"&IF(Dashboard!$B$4="",2958465,Dashboard!$B$4+1)),COUNTIFS(Summary!$E$2:$E$240,$A6,Summary!$D$2:$D$240,">="&T4,Summary!$D$2:$D$240,"<"&T4+7,Summary!$A$2:$A$240,">="&IF(Dashboard!$B$3="",0,Dashboard!$B$3),Summary!$A$2:$A$240,"<"&IF(Dashboard!$B$4="",2958465,Dashboard!$B$4+1)))) -> 0
A7: =IF(Settings!A6="","",Settings!A6) -> Door Gasket | B7: =IF($A7="","",IF(hm_basis="Call date",COUNTIFS(Summary!$E$2:$E$240,$A7,Summary!$A$2:$A$240,">="&B4,Summary!$A$2:$A$240,"<"&B4+7,Summary!$A$2:$A$240,">="&IF(Dashboard!$B$3="",0,Dashboard!$B$3),Summary!$A$2:$A$240,"<"&IF(Dashboard!$B$4="",2958465,Dashboard!$B$4+1)),COUNTIFS(Summary!$E$2:$E$240,$A7,Summary!$D$2:$D$240,">="&B4,Summary!$D$2:$D$240,"<"&B4+7,Summary!$A$2:$A$240,">="&IF(Dashboard!$B$3="",0,Dashboard!$B$3),Summary!$A$2:$A$240,"<"&IF(Dashboard!$B$4="",2958465,Dashboard!$B$4+1)))) -> 0 | C7: =IF($A7="","",IF(hm_basis="Call date",COUNTIFS(Summary!$E$2:$E$240,$A7,Summary!$A$2:$A$240,">="&C4,Summary!$A$2:$A$240,"<"&C4+7,Summary!$A$2:$A$240,">="&IF(Dashboard!$B$3="",0,Dashboard!$B$3),Summary!$A$2:$A$240,"<"&IF(Dashboard!$B$4="",2958465,Dashboard!$B$4+1)),COUNTIFS(Summary!$E$2:$E$240,$A7,Summary!$D$2:$D$240,">="&C4,Summary!$D$2:$D$240,"<"&C4+7,Summary!$A$2:$A$240,">="&IF(Dashboard!$B$3="",0,Dashboard!$B$3),Summary!$A$2:$A$240,"<"&IF(Dashboard!$B$4="",2958465,Dashboard!$B$4+1)))) -> 2 | D7: =IF($A7="","",IF(hm_basis="Call date",COUNTIFS(Summary!$E$2:$E$240,$A7,Summary!$A$2:$A$240,">="&D4,Summary!$A$2:$A$240,"<"&D4+7,Summary!$A$2:$A$240,">="&IF(Dashboard!$B$3="",0,Dashboard!$B$3),Summary!$A$2:$A$240,"<"&IF(Dashboard!$B$4="",2958465,Dashboard!$B$4+1)),COUNTIFS(Summary!$E$2:$E$240,$A7,Summary!$D$2:$D$240,">="&D4,Summary!$D$2:$D$240,"<"&D4+7,Summary!$A$2:$A$240,">="&IF(Dashboard!$B$3="",0,Dashboard!$B$3),Summary!$A$2:$A$240,"<"&IF(Dashboard!$B$4="",2958465,Dashboard!$B$4+1)))) -> 0 | E7: =IF($A7="","",IF(hm_basis="Call date",COUNTIFS(Summary!$E$2:$E$240,$A7,Summary!$A$2:$A$240,">="&E4,Summary!$A$2:$A$240,"<"&E4+7,Summary!$A$2:$A$240,">="&IF(Dashboard!$B$3="",0,Dashboard!$B$3),Summary!$A$2:$A$240,"<"&IF(Dashboard!$B$4="",2958465,Dashboard!$B$4+1)),COUNTIFS(Summary!$E$2:$E$240,$A7,Summary!$D$2:$D$240,">="&E4,Summary!$D$2:$D$240,"<"&E4+7,Summary!$A$2:$A$240,">="&IF(Dashboard!$B$3="",0,Dashboard!$B$3),Summary!$A$2:$A$240,"<"&IF(Dashboard!$B$4="",2958465,Dashboard!$B$4+1)))) -> 1 | F7: =IF($A7="","",IF(hm_basis="Call date",COUNTIFS(Summary!$E$2:$E$240,$A7,Summary!$A$2:$A$240,">="&F4,Summary!$A$2:$A$240,"<"&F4+7,Summary!$A$2:$A$240,">="&IF(Dashboard!$B$3="",0,Dashboard!$B$3),Summary!$A$2:$A$240,"<"&IF(Dashboard!$B$4="",2958465,Dashboard!$B$4+1)),COUNTIFS(Summary!$E$2:$E$240,$A7,Summary!$D$2:$D$240,">="&F4,Summary!$D$2:$D$240,"<"&F4+7,Summary!$A$2:$A$240,">="&IF(Dashboard!$B$3="",0,Dashboard!$B$3),Summary!$A$2:$A$240,"<"&IF(Dashboard!$B$4="",2958465,Dashboard!$B$4+1)))) -> 0 | G7: =IF($A7="","",IF(hm_basis="Call date",COUNTIFS(Summary!$E$2:$E$240,$A7,Summary!$A$2:$A$240,">="&G4,Summary!$A$2:$A$240,"<"&G4+7,Summary!$A$2:$A$240,">="&IF(Dashboard!$B$3="",0,Dashboard!$B$3),Summary!$A$2:$A$240,"<"&IF(Dashboard!$B$4="",2958465,Dashboard!$B$4+1)),COUNTIFS(Summary!$E$2:$E$240,$A7,Summary!$D$2:$D$240,">="&G4,Summary!$D$2:$D$240,"<"&G4+7,Summary!$A$2:$A$240,">="&IF(Dashboard!$B$3="",0,Dashboard!$B$3),Summary!$A$2:$A$240,"<"&IF(Dashboard!$B$4="",2958465,Dashboard!$B$4+1)))) -> 0 | H7: =IF($A7="","",IF(hm_basis="Call date",COUNTIFS(Summary!$E$2:$E$240,$A7,Summary!$A$2:$A$240,">="&H4,Summary!$A$2:$A$240,"<"&H4+7,Summary!$A$2:$A$240,">="&IF(Dashboard!$B$3="",0,Dashboard!$B$3),Summary!$A$2:$A$240,"<"&IF(Dashboard!$B$4="",2958465,Dashboard!$B$4+1)),COUNTIFS(Summary!$E$2:$E$240,$A7,Summary!$D$2:$D$240,">="&H4,Summary!$D$2:$D$240,"<"&H4+7,Summary!$A$2:$A$240,">="&IF(Dashboard!$B$3="",0,Dashboard!$B$3),Summary!$A$2:$A$240,"<"&IF(Dashboard!$B$4="",2958465,Dashboard!$B$4+1)))) -> 0 | I7: =IF($A7="","",IF(hm_basis="Call date",COUNTIFS(Summary!$E$2:$E$240,$A7,Summary!$A$2:$A$240,">="&I4,Summary!$A$2:$A$240,"<"&I4+7,Summary!$A$2:$A$240,">="&IF(Dashboard!$B$3="",0,Dashboard!$B$3),Summary!$A$2:$A$240,"<"&IF(Dashboard!$B$4="",2958465,Dashboard!$B$4+1)),COUNTIFS(Summary!$E$2:$E$240,$A7,Summary!$D$2:$D$240,">="&I4,Summary!$D$2:$D$240,"<"&I4+7,Summary!$A$2:$A$240,">="&IF(Dashboard!$B$3="",0,Dashboard!$B$3),Summary!$A$2:$A$240,"<"&IF(Dashboard!$B$4="",2958465,Dashboard!$B$4+1)))) -> 0 | ... T7: =IF($A7="","",IF(hm_basis="Call date",COUNTIFS(Summary!$E$2:$E$240,$A7,Summary!$A$2:$A$240,">="&T4,Summary!$A$2:$A$240,"<"&T4+7,Summary!$A$2:$A$240,">="&IF(Dashboard!$B$3="",0,Dashboard!$B$3),Summary!$A$2:$A$240,"<"&IF(Dashboard!$B$4="",2958465,Dashboard!$B$4+1)),COUNTIFS(Summary!$E$2:$E$240,$A7,Summary!$D$2:$D$240,">="&T4,Summary!$D$2:$D$240,"<"&T4+7,Summary!$A$2:$A$240,">="&IF(Dashboard!$B$3="",0,Dashboard!$B$3),Summary!$A$2:$A$240,"<"&IF(Dashboard!$B$4="",2958465,Dashboard!$B$4+1)))) -> 0
A8: =IF(Settings!A7="","",Settings!A7) -> Door frame heater | B8: =IF($A8="","",IF(hm_basis="Call date",COUNTIFS(Summary!$E$2:$E$240,$A8,Summary!$A$2:$A$240,">="&B4,Summary!$A$2:$A$240,"<"&B4+7,Summary!$A$2:$A$240,">="&IF(Dashboard!$B$3="",0,Dashboard!$B$3),Summary!$A$2:$A$240,"<"&IF(Dashboard!$B$4="",2958465,Dashboard!$B$4+1)),COUNTIFS(Summary!$E$2:$E$240,$A8,Summary!$D$2:$D$240,">="&B4,Summary!$D$2:$D$240,"<"&B4+7,Summary!$A$2:$A$240,">="&IF(Dashboard!$B$3="",0,Dashboard!$B$3),Summary!$A$2:$A$240,"<"&IF(Dashboard!$B$4="",2958465,Dashboard!$B$4+1)))) -> 1 | C8: =IF($A8="","",IF(hm_basis="Call date",COUNTIFS(Summary!$E$2:$E$240,$A8,Summary!$A$2:$A$240,">="&C4,Summary!$A$2:$A$240,"<"&C4+7,Summary!$A$2:$A$240,">="&IF(Dashboard!$B$3="",0,Dashboard!$B$3),Summary!$A$2:$A$240,"<"&IF(Dashboard!$B$4="",2958465,Dashboard!$B$4+1)),COUNTIFS(Summary!$E$2:$E$240,$A8,Summary!$D$2:$D$240,">="&C4,Summary!$D$2:$D$240,"<"&C4+7,Summary!$A$2:$A$240,">="&IF(Dashboard!$B$3="",0,Dashboard!$B$3),Summary!$A$2:$A$240,"<"&IF(Dashboard!$B$4="",2958465,Dashboard!$B$4+1)))) -> 1 | D8: =IF($A8="","",IF(hm_basis="Call date",COUNTIFS(Summary!$E$2:$E$240,$A8,Summary!$A$2:$A$240,">="&D4,Summary!$A$2:$A$240,"<"&D4+7,Summary!$A$2:$A$240,">="&IF(Dashboard!$B$3="",0,Dashboard!$B$3),Summary!$A$2:$A$240,"<"&IF(Dashboard!$B$4="",2958465,Dashboard!$B$4+1)),COUNTIFS(Summary!$E$2:$E$240,$A8,Summary!$D$2:$D$240,">="&D4,Summary!$D$2:$D$240,"<"&D4+7,Summary!$A$2:$A$240,">="&IF(Dashboard!$B$3="",0,Dashboard!$B$3),Summary!$A$2:$A$240,"<"&IF(Dashboard!$B$4="",2958465,Dashboard!$B$4+1)))) -> 0 | E8: =IF($A8="","",IF(hm_basis="Call date",COUNTIFS(Summary!$E$2:$E$240,$A8,Summary!$A$2:$A$240,">="&E4,Summary!$A$2:$A$240,"<"&E4+7,Summary!$A$2:$A$240,">="&IF(Dashboard!$B$3="",0,Dashboard!$B$3),Summary!$A$2:$A$240,"<"&IF(Dashboard!$B$4="",2958465,Dashboard!$B$4+1)),COUNTIFS(Summary!$E$2:$E$240,$A8,Summary!$D$2:$D$240,">="&E4,Summary!$D$2:$D$240,"<"&E4+7,Summary!$A$2:$A$240,">="&IF(Dashboard!$B$3="",0,Dashboard!$B$3),Summary!$A$2:$A$240,"<"&IF(Dashboard!$B$4="",2958465,Dashboard!$B$4+1)))) -> 0 | F8: =IF($A8="","",IF(hm_basis="Call date",COUNTIFS(Summary!$E$2:$E$240,$A8,Summary!$A$2:$A$240,">="&F4,Summary!$A$2:$A$240,"<"&F4+7,Summary!$A$2:$A$240,">="&IF(Dashboard!$B$3="",0,Dashboard!$B$3),Summary!$A$2:$A$240,"<"&IF(Dashboard!$B$4="",2958465,Dashboard!$B$4+1)),COUNTIFS(Summary!$E$2:$E$240,$A8,Summary!$D$2:$D$240,">="&F4,Summary!$D$2:$D$240,"<"&F4+7,Summary!$A$2:$A$240,">="&IF(Dashboard!$B$3="",0,Dashboard!$B$3),Summary!$A$2:$A$240,"<"&IF(Dashboard!$B$4="",2958465,Dashboard!$B$4+1)))) -> 1 | G8: =IF($A8="","",IF(hm_basis="Call date",COUNTIFS(Summary!$E$2:$E$240,$A8,Summary!$A$2:$A$240,">="&G4,Summary!$A$2:$A$240,"<"&G4+7,Summary!$A$2:$A$240,">="&IF(Dashboard!$B$3="",0,Dashboard!$B$3),Summary!$A$2:$A$240,"<"&IF(Dashboard!$B$4="",2958465,Dashboard!$B$4+1)),COUNTIFS(Summary!$E$2:$E$240,$A8,Summary!$D$2:$D$240,">="&G4,Summary!$D$2:$D$240,"<"&G4+7,Summary!$A$2:$A$240,">="&IF(Dashboard!$B$3="",0,Dashboard!$B$3),Summary!$A$2:$A$240,"<"&IF(Dashboard!$B$4="",2958465,Dashboard!$B$4+1)))) -> 0 | H8: =IF($A8="","",IF(hm_basis="Call date",COUNTIFS(Summary!$E$2:$E$240,$A8,Summary!$A$2:$A$240,">="&H4,Summary!$A$2:$A$240,"<"&H4+7,Summary!$A$2:$A$240,">="&IF(Dashboard!$B$3="",0,Dashboard!$B$3),Summary!$A$2:$A$240,"<"&IF(Dashboard!$B$4="",2958465,Dashboard!$B$4+1)),COUNTIFS(Summary!$E$2:$E$240,$A8,Summary!$D$2:$D$240,">="&H4,Summary!$D$2:$D$240,"<"&H4+7,Summary!$A$2:$A$240,">="&IF(Dashboard!$B$3="",0,Dashboard!$B$3),Summary!$A$2:$A$240,"<"&IF(Dashboard!$B$4="",2958465,Dashboard!$B$4+1)))) -> 0 | I8: =IF($A8="","",IF(hm_basis="Call date",COUNTIFS(Summary!$E$2:$E$240,$A8,Summary!$A$2:$A$240,">="&I4,Summary!$A$2:$A$240,"<"&I4+7,Summary!$A$2:$A$240,">="&IF(Dashboard!$B$3="",0,Dashboard!$B$3),Summary!$A$2:$A$240,"<"&IF(Dashboard!$B$4="",2958465,Dashboard!$B$4+1)),COUNTIFS(Summary!$E$2:$E$240,$A8,Summary!$D$2:$D$240,">="&I4,Summary!$D$2:$D$240,"<"&I4+7,Summary!$A$2:$A$240,">="&IF(Dashboard!$B$3="",0,Dashboard!$B$3),Summary!$A$2:$A$240,"<"&IF(Dashboard!$B$4="",2958465,Dashboard!$B$4+1)))) -> 0 | ... T8: =IF($A8="","",IF(hm_basis="Call date",COUNTIFS(Summary!$E$2:$E$240,$A8,Summary!$A$2:$A$240,">="&T4,Summary!$A$2:$A$240,"<"&T4+7,Summary!$A$2:$A$240,">="&IF(Dashboard!$B$3="",0,Dashboard!$B$3),Summary!$A$2:$A$240,"<"&IF(Dashboard!$B$4="",2958465,Dashboard!$B$4+1)),COUNTIFS(Summary!$E$2:$E$240,$A8,Summary!$D$2:$D$240,">="&T4,Summary!$D$2:$D$240,"<"&T4+7,Summary!$A$2:$A$240,">="&IF(Dashboard!$B$3="",0,Dashboard!$B$3),Summary!$A$2:$A$240,"<"&IF(Dashboard!$B$4="",2958465,Dashboard!$B$4+1)))) -> 0
A9: =IF(Settings!A8="","",Settings!A8) -> Door Torsion rod | B9: =IF($A9="","",IF(hm_basis="Call date",COUNTIFS(Summary!$E$2:$E$240,$A9,Summary!$A$2:$A$240,">="&B4,Summary!$A$2:$A$240,"<"&B4+7,Summary!$A$2:$A$240,">="&IF(Dashboard!$B$3="",0,Dashboard!$B$3),Summary!$A$2:$A$240,"<"&IF(Dashboard!$B$4="",2958465,Dashboard!$B$4+1)),COUNTIFS(Summary!$E$2:$E$240,$A9,Summary!$D$2:$D$240,">="&B4,Summary!$D$2:$D$240,"<"&B4+7,Summary!$A$2:$A$240,">="&IF(Dashboard!$B$3="",0,Dashboard!$B$3),Summary!$A$2:$A$240,"<"&IF(Dashboard!$B$4="",2958465,Dashboard!$B$4+1)))) -> 0 | C9: =IF($A9="","",IF(hm_basis="Call date",COUNTIFS(Summary!$E$2:$E$240,$A9,Summary!$A$2:$A$240,">="&C4,Summary!$A$2:$A$240,"<"&C4+7,Summary!$A$2:$A$240,">="&IF(Dashboard!$B$3="",0,Dashboard!$B$3),Summary!$A$2:$A$240,"<"&IF(Dashboard!$B$4="",2958465,Dashboard!$B$4+1)),COUNTIFS(Summary!$E$2:$E$240,$A9,Summary!$D$2:$D$240,">="&C4,Summary!$D$2:$D$240,"<"&C4+7,Summary!$A$2:$A$240,">="&IF(Dashboard!$B$3="",0,Dashboard!$B$3),Summary!$A$2:$A$240,"<"&IF(Dashboard!$B$4="",2958465,Dashboard!$B$4+1)))) -> 0 | D9: =IF($A9="","",IF(hm_basis="Call date",COUNTIFS(Summary!$E$2:$E$240,$A9,Summary!$A$2:$A$240,">="&D4,Summary!$A$2:$A$240,"<"&D4+7,Summary!$A$2:$A$240,">="&IF(Dashboard!$B$3="",0,Dashboard!$B$3),Summary!$A$2:$A$240,"<"&IF(Dashboard!$B$4="",2958465,Dashboard!$B$4+1)),COUNTIFS(Summary!$E$2:$E$240,$A9,Summary!$D$2:$D$240,">="&D4,Summary!$D$2:$D$240,"<"&D4+7,Summary!$A$2:$A$240,">="&IF(Dashboard!$B$3="",0,Dashboard!$B$3),Summary!$A$2:$A$240,"<"&IF(Dashboard!$B$4="",2958465,Dashboard!$B$4+1)))) -> 0 | E9: =IF($A9="","",IF(hm_basis="Call date",COUNTIFS(Summary!$E$2:$E$240,$A9,Summary!$A$2:$A$240,">="&E4,Summary!$A$2:$A$240,"<"&E4+7,Summary!$A$2:$A$240,">="&IF(Dashboard!$B$3="",0,Dashboard!$B$3),Summary!$A$2:$A$240,"<"&IF(Dashboard!$B$4="",2958465,Dashboard!$B$4+1)),COUNTIFS(Summary!$E$2:$E$240,$A9,Summary!$D$2:$D$240,">="&E4,Summary!$D$2:$D$240,"<"&E4+7,Summary!$A$2:$A$240,">="&IF(Dashboard!$B$3="",0,Dashboard!$B$3),Summary!$A$2:$A$240,"<"&IF(Dashboard!$B$4="",2958465,Dashboard!$B$4+1)))) -> 0 | F9: =IF($A9="","",IF(hm_basis="Call date",COUNTIFS(Summary!$E$2:$E$240,$A9,Summary!$A$2:$A$240,">="&F4,Summary!$A$2:$A$240,"<"&F4+7,Summary!$A$2:$A$240,">="&IF(Dashboard!$B$3="",0,Dashboard!$B$3),Summary!$A$2:$A$240,"<"&IF(Dashboard!$B$4="",2958465,Dashboard!$B$4+1)),COUNTIFS(Summary!$E$2:$E$240,$A9,Summary!$D$2:$D$240,">="&F4,Summary!$D$2:$D$240,"<"&F4+7,Summary!$A$2:$A$240,">="&IF(Dashboard!$B$3="",0,Dashboard!$B$3),Summary!$A$2:$A$240,"<"&IF(Dashboard!$B$4="",2958465,Dashboard!$B$4+1)))) -> 1 | G9: =IF($A9="","",IF(hm_basis="Call date",COUNTIFS(Summary!$E$2:$E$240,$A9,Summary!$A$2:$A$240,">="&G4,Summary!$A$2:$A$240,"<"&G4+7,Summary!$A$2:$A$240,">="&IF(Dashboard!$B$3="",0,Dashboard!$B$3),Summary!$A$2:$A$240,"<"&IF(Dashboard!$B$4="",2958465,Dashboard!$B$4+1)),COUNTIFS(Summary!$E$2:$E$240,$A9,Summary!$D$2:$D$240,">="&G4,Summary!$D$2:$D$240,"<"&G4+7,Summary!$A$2:$A$240,">="&IF(Dashboard!$B$3="",0,Dashboard!$B$3),Summary!$A$2:$A$240,"<"&IF(Dashboard!$B$4="",2958465,Dashboard!$B$4+1)))) -> 0 | H9: =IF($A9="","",IF(hm_basis="Call date",COUNTIFS(Summary!$E$2:$E$240,$A9,Summary!$A$2:$A$240,">="&H4,Summary!$A$2:$A$240,"<"&H4+7,Summary!$A$2:$A$240,">="&IF(Dashboard!$B$3="",0,Dashboard!$B$3),Summary!$A$2:$A$240,"<"&IF(Dashboard!$B$4="",2958465,Dashboard!$B$4+1)),COUNTIFS(Summary!$E$2:$E$240,$A9,Summary!$D$2:$D$240,">="&H4,Summary!$D$2:$D$240,"<"&H4+7,Summary!$A$2:$A$240,">="&IF(Dashboard!$B$3="",0,Dashboard!$B$3),Summary!$A$2:$A$240,"<"&IF(Dashboard!$B$4="",2958465,Dashboard!$B$4+1)))) -> 0 | I9: =IF($A9="","",IF(hm_basis="Call date",COUNTIFS(Summary!$E$2:$E$240,$A9,Summary!$A$2:$A$240,">="&I4,Summary!$A$2:$A$240,"<"&I4+7,Summary!$A$2:$A$240,">="&IF(Dashboard!$B$3="",0,Dashboard!$B$3),Summary!$A$2:$A$240,"<"&IF(Dashboard!$B$4="",2958465,Dashboard!$B$4+1)),COUNTIFS(Summary!$E$2:$E$240,$A9,Summary!$D$2:$D$240,">="&I4,Summary!$D$2:$D$240,"<"&I4+7,Summary!$A$2:$A$240,">="&IF(Dashboard!$B$3="",0,Dashboard!$B$3),Summary!$A$2:$A$240,"<"&IF(Dashboard!$B$4="",2958465,Dashboard!$B$4+1)))) -> 0 | ... T9: =IF($A9="","",IF(hm_basis="Call date",COUNTIFS(Summary!$E$2:$E$240,$A9,Summary!$A$2:$A$240,">="&T4,Summary!$A$2:$A$240,"<"&T4+7,Summary!$A$2:$A$240,">="&IF(Dashboard!$B$3="",0,Dashboard!$B$3),Summary!$A$2:$A$240,"<"&IF(Dashboard!$B$4="",2958465,Dashboard!$B$4+1)),COUNTIFS(Summary!$E$2:$E$240,$A9,Summary!$D$2:$D$240,">="&T4,Summary!$D$2:$D$240,"<"&T4+7,Summary!$A$2:$A$240,">="&IF(Dashboard!$B$3="",0,Dashboard!$B$3),Summary!$A$2:$A$240,"<"&IF(Dashboard!$B$4="",2958465,Dashboard!$B$4+1)))) -> 0
A10: =IF(Settings!A9="","",Settings!A9) -> Door not closed (Overnight) | B10: =IF($A10="","",IF(hm_basis="Call date",COUNTIFS(Summary!$E$2:$E$240,$A10,Summary!$A$2:$A$240,">="&B4,Summary!$A$2:$A$240,"<"&B4+7,Summary!$A$2:$A$240,">="&IF(Dashboard!$B$3="",0,Dashboard!$B$3),Summary!$A$2:$A$240,"<"&IF(Dashboard!$B$4="",2958465,Dashboard!$B$4+1)),COUNTIFS(Summary!$E$2:$E$240,$A10,Summary!$D$2:$D$240,">="&B4,Summary!$D$2:$D$240,"<"&B4+7,Summary!$A$2:$A$240,">="&IF(Dashboard!$B$3="",0,Dashboard!$B$3),Summary!$A$2:$A$240,"<"&IF(Dashboard!$B$4="",2958465,Dashboard!$B$4+1)))) -> 1 | C10: =IF($A10="","",IF(hm_basis="Call date",COUNTIFS(Summary!$E$2:$E$240,$A10,Summary!$A$2:$A$240,">="&C4,Summary!$A$2:$A$240,"<"&C4+7,Summary!$A$2:$A$240,">="&IF(Dashboard!$B$3="",0,Dashboard!$B$3),Summary!$A$2:$A$240,"<"&IF(Dashboard!$B$4="",2958465,Dashboard!$B$4+1)),COUNTIFS(Summary!$E$2:$E$240,$A10,Summary!$D$2:$D$240,">="&C4,Summary!$D$2:$D$240,"<"&C4+7,Summary!$A$2:$A$240,">="&IF(Dashboard!$B$3="",0,Dashboard!$B$3),Summary!$A$2:$A$240,"<"&IF(Dashboard!$B$4="",2958465,Dashboard!$B$4+1)))) -> 1 | D10: =IF($A10="","",IF(hm_basis="Call date",COUNTIFS(Summary!$E$2:$E$240,$A10,Summary!$A$2:$A$240,">="&D4,Summary!$A$2:$A$240,"<"&D4+7,Summary!$A$2:$A$240,">="&IF(Dashboard!$B$3="",0,Dashboard!$B$3),Summary!$A$2:$A$240,"<"&IF(Dashboard!$B$4="",2958465,Dashboard!$B$4+1)),COUNTIFS(Summary!$E$2:$E$240,$A10,Summary!$D$2:$D$240,">="&D4,Summary!$D$2:$D$240,"<"&D4+7,Summary!$A$2:$A$240,">="&IF(Dashboard!$B$3="",0,Dashboard!$B$3),Summary!$A$2:$A$240,"<"&IF(Dashboard!$B$4="",2958465,Dashboard!$B$4+1)))) -> 4 | E10: =IF($A10="","",IF(hm_basis="Call date",COUNTIFS(Summary!$E$2:$E$240,$A10,Summary!$A$2:$A$240,">="&E4,Summary!$A$2:$A$240,"<"&E4+7,Summary!$A$2:$A$240,">="&IF(Dashboard!$B$3="",0,Dashboard!$B$3),Summary!$A$2:$A$240,"<"&IF(Dashboard!$B$4="",2958465,Dashboard!$B$4+1)),COUNTIFS(Summary!$E$2:$E$240,$A10,Summary!$D$2:$D$240,">="&E4,Summary!$D$2:$D$240,"<"&E4+7,Summary!$A$2:$A$240,">="&IF(Dashboard!$B$3="",0,Dashboard!$B$3),Summary!$A$2:$A$240,"<"&IF(Dashboard!$B$4="",2958465,Dashboard!$B$4+1)))) -> 2 | F10: =IF($A10="","",IF(hm_basis="Call date",COUNTIFS(Summary!$E$2:$E$240,$A10,Summary!$A$2:$A$240,">="&F4,Summary!$A$2:$A$240,"<"&F4+7,Summary!$A$2:$A$240,">="&IF(Dashboard!$B$3="",0,Dashboard!$B$3),Summary!$A$2:$A$240,"<"&IF(Dashboard!$B$4="",2958465,Dashboard!$B$4+1)),COUNTIFS(Summary!$E$2:$E$240,$A10,Summary!$D$2:$D$240,">="&F4,Summary!$D$2:$D$240,"<"&F4+7,Summary!$A$2:$A$240,">="&IF(Dashboard!$B$3="",0,Dashboard!$B$3),Summary!$A$2:$A$240,"<"&IF(Dashboard!$B$4="",2958465,Dashboard!$B$4+1)))) -> 4 | G10: =IF($A10="","",IF(hm_basis="Call date",COUNTIFS(Summary!$E$2:$E$240,$A10,Summary!$A$2:$A$240,">="&G4,Summary!$A$2:$A$240,"<"&G4+7,Summary!$A$2:$A$240,">="&IF(Dashboard!$B$3="",0,Dashboard!$B$3),Summary!$A$2:$A$240,"<"&IF(Dashboard!$B$4="",2958465,Dashboard!$B$4+1)),COUNTIFS(Summary!$E$2:$E$240,$A10,Summary!$D$2:$D$240,">="&G4,Summary!$D$2:$D$240,"<"&G4+7,Summary!$A$2:$A$240,">="&IF(Dashboard!$B$3="",0,Dashboard!$B$3),Summary!$A$2:$A$240,"<"&IF(Dashboard!$B$4="",2958465,Dashboard!$B$4+1)))) -> 1 | H10: =IF($A10="","",IF(hm_basis="Call date",COUNTIFS(Summary!$E$2:$E$240,$A10,Summary!$A$2:$A$240,">="&H4,Summary!$A$2:$A$240,"<"&H4+7,Summary!$A$2:$A$240,">="&IF(Dashboard!$B$3="",0,Dashboard!$B$3),Summary!$A$2:$A$240,"<"&IF(Dashboard!$B$4="",2958465,Dashboard!$B$4+1)),COUNTIFS(Summary!$E$2:$E$240,$A10,Summary!$D$2:$D$240,">="&H4,Summary!$D$2:$D$240,"<"&H4+7,Summary!$A$2:$A$240,">="&IF(Dashboard!$B$3="",0,Dashboard!$B$3),Summary!$A$2:$A$240,"<"&IF(Dashboard!$B$4="",2958465,Dashboard!$B$4+1)))) -> 0 | I10: =IF($A10="","",IF(hm_basis="Call date",COUNTIFS(Summary!$E$2:$E$240,$A10,Summary!$A$2:$A$240,">="&I4,Summary!$A$2:$A$240,"<"&I4+7,Summary!$A$2:$A$240,">="&IF(Dashboard!$B$3="",0,Dashboard!$B$3),Summary!$A$2:$A$240,"<"&IF(Dashboard!$B$4="",2958465,Dashboard!$B$4+1)),COUNTIFS(Summary!$E$2:$E$240,$A10,Summary!$D$2:$D$240,">="&I4,Summary!$D$2:$D$240,"<"&I4+7,Summary!$A$2:$A$240,">="&IF(Dashboard!$B$3="",0,Dashboard!$B$3),Summary!$A$2:$A$240,"<"&IF(Dashboard!$B$4="",2958465,Dashboard!$B$4+1)))) -> 0 | ... T10: =IF($A10="","",IF(hm_basis="Call date",COUNTIFS(Summary!$E$2:$E$240,$A10,Summary!$A$2:$A$240,">="&T4,Summary!$A$2:$A$240,"<"&T4+7,Summary!$A$2:$A$240,">="&IF(Dashboard!$B$3="",0,Dashboard!$B$3),Summary!$A$2:$A$240,"<"&IF(Dashboard!$B$4="",2958465,Dashboard!$B$4+1)),COUNTIFS(Summary!$E$2:$E$240,$A10,Summary!$D$2:$D$240,">="&T4,Summary!$D$2:$D$240,"<"&T4+7,Summary!$A$2:$A$240,">="&IF(Dashboard!$B$3="",0,Dashboard!$B$3),Summary!$A$2:$A$240,"<"&IF(Dashboard!$B$4="",2958465,Dashboard!$B$4+1)))) -> 0
A11: =IF(Settings!A10="","",Settings!A10) -> Door - general | B11: =IF($A11="","",IF(hm_basis="Call date",COUNTIFS(Summary!$E$2:$E$240,$A11,Summary!$A$2:$A$240,">="&B4,Summary!$A$2:$A$240,"<"&B4+7,Summary!$A$2:$A$240,">="&IF(Dashboard!$B$3="",0,Dashboard!$B$3),Summary!$A$2:$A$240,"<"&IF(Dashboard!$B$4="",2958465,Dashboard!$B$4+1)),COUNTIFS(Summary!$E$2:$E$240,$A11,Summary!$D$2:$D$240,">="&B4,Summary!$D$2:$D$240,"<"&B4+7,Summary!$A$2:$A$240,">="&IF(Dashboard!$B$3="",0,Dashboard!$B$3),Summary!$A$2:$A$240,"<"&IF(Dashboard!$B$4="",2958465,Dashboard!$B$4+1)))) -> 0 | C11: =IF($A11="","",IF(hm_basis="Call date",COUNTIFS(Summary!$E$2:$E$240,$A11,Summary!$A$2:$A$240,">="&C4,Summary!$A$2:$A$240,"<"&C4+7,Summary!$A$2:$A$240,">="&IF(Dashboard!$B$3="",0,Dashboard!$B$3),Summary!$A$2:$A$240,"<"&IF(Dashboard!$B$4="",2958465,Dashboard!$B$4+1)),COUNTIFS(Summary!$E$2:$E$240,$A11,Summary!$D$2:$D$240,">="&C4,Summary!$D$2:$D$240,"<"&C4+7,Summary!$A$2:$A$240,">="&IF(Dashboard!$B$3="",0,Dashboard!$B$3),Summary!$A$2:$A$240,"<"&IF(Dashboard!$B$4="",2958465,Dashboard!$B$4+1)))) -> 0 | D11: =IF($A11="","",IF(hm_basis="Call date",COUNTIFS(Summary!$E$2:$E$240,$A11,Summary!$A$2:$A$240,">="&D4,Summary!$A$2:$A$240,"<"&D4+7,Summary!$A$2:$A$240,">="&IF(Dashboard!$B$3="",0,Dashboard!$B$3),Summary!$A$2:$A$240,"<"&IF(Dashboard!$B$4="",2958465,Dashboard!$B$4+1)),COUNTIFS(Summary!$E$2:$E$240,$A11,Summary!$D$2:$D$240,">="&D4,Summary!$D$2:$D$240,"<"&D4+7,Summary!$A$2:$A$240,">="&IF(Dashboard!$B$3="",0,Dashboard!$B$3),Summary!$A$2:$A$240,"<"&IF(Dashboard!$B$4="",2958465,Dashboard!$B$4+1)))) -> 0 | E11: =IF($A11="","",IF(hm_basis="Call date",COUNTIFS(Summary!$E$2:$E$240,$A11,Summary!$A$2:$A$240,">="&E4,Summary!$A$2:$A$240,"<"&E4+7,Summary!$A$2:$A$240,">="&IF(Dashboard!$B$3="",0,Dashboard!$B$3),Summary!$A$2:$A$240,"<"&IF(Dashboard!$B$4="",2958465,Dashboard!$B$4+1)),COUNTIFS(Summary!$E$2:$E$240,$A11,Summary!$D$2:$D$240,">="&E4,Summary!$D$2:$D$240,"<"&E4+7,Summary!$A$2:$A$240,">="&IF(Dashboard!$B$3="",0,Dashboard!$B$3),Summary!$A$2:$A$240,"<"&IF(Dashboard!$B$4="",2958465,Dashboard!$B$4+1)))) -> 0 | F11: =IF($A11="","",IF(hm_basis="Call date",COUNTIFS(Summary!$E$2:$E$240,$A11,Summary!$A$2:$A$240,">="&F4,Summary!$A$2:$A$240,"<"&F4+7,Summary!$A$2:$A$240,">="&IF(Dashboard!$B$3="",0,Dashboard!$B$3),Summary!$A$2:$A$240,"<"&IF(Dashboard!$B$4="",2958465,Dashboard!$B$4+1)),COUNTIFS(Summary!$E$2:$E$240,$A11,Summary!$D$2:$D$240,">="&F4,Summary!$D$2:$D$240,"<"&F4+7,Summary!$A$2:$A$240,">="&IF(Dashboard!$B$3="",0,Dashboard!$B$3),Summary!$A$2:$A$240,"<"&IF(Dashboard!$B$4="",2958465,Dashboard!$B$4+1)))) -> 0 | G11: =IF($A11="","",IF(hm_basis="Call date",COUNTIFS(Summary!$E$2:$E$240,$A11,Summary!$A$2:$A$240,">="&G4,Summary!$A$2:$A$240,"<"&G4+7,Summary!$A$2:$A$240,">="&IF(Dashboard!$B$3="",0,Dashboard!$B$3),Summary!$A$2:$A$240,"<"&IF(Dashboard!$B$4="",2958465,Dashboard!$B$4+1)),COUNTIFS(Summary!$E$2:$E$240,$A11,Summary!$D$2:$D$240,">="&G4,Summary!$D$2:$D$240,"<"&G4+7,Summary!$A$2:$A$240,">="&IF(Dashboard!$B$3="",0,Dashboard!$B$3),Summary!$A$2:$A$240,"<"&IF(Dashboard!$B$4="",2958465,Dashboard!$B$4+1)))) -> 0 | H11: =IF($A11="","",IF(hm_basis="Call date",COUNTIFS(Summary!$E$2:$E$240,$A11,Summary!$A$2:$A$240,">="&H4,Summary!$A$2:$A$240,"<"&H4+7,Summary!$A$2:$A$240,">="&IF(Dashboard!$B$3="",0,Dashboard!$B$3),Summary!$A$2:$A$240,"<"&IF(Dashboard!$B$4="",2958465,Dashboard!$B$4+1)),COUNTIFS(Summary!$E$2:$E$240,$A11,Summary!$D$2:$D$240,">="&H4,Summary!$D$2:$D$240,"<"&H4+7,Summary!$A$2:$A$240,">="&IF(Dashboard!$B$3="",0,Dashboard!$B$3),Summary!$A$2:$A$240,"<"&IF(Dashboard!$B$4="",2958465,Dashboard!$B$4+1)))) -> 1 | I11: =IF($A11="","",IF(hm_basis="Call date",COUNTIFS(Summary!$E$2:$E$240,$A11,Summary!$A$2:$A$240,">="&I4,Summary!$A$2:$A$240,"<"&I4+7,Summary!$A$2:$A$240,">="&IF(Dashboard!$B$3="",0,Dashboard!$B$3),Summary!$A$2:$A$240,"<"&IF(Dashboard!$B$4="",2958465,Dashboard!$B$4+1)),COUNTIFS(Summary!$E$2:$E$240,$A11,Summary!$D$2:$D$240,">="&I4,Summary!$D$2:$D$240,"<"&I4+7,Summary!$A$2:$A$240,">="&IF(Dashboard!$B$3="",0,Dashboard!$B$3),Summary!$A$2:$A$240,"<"&IF(Dashboard!$B$4="",2958465,Dashboard!$B$4+1)))) -> 0 | ... T11: =IF($A11="","",IF(hm_basis="Call date",COUNTIFS(Summary!$E$2:$E$240,$A11,Summary!$A$2:$A$240,">="&T4,Summary!$A$2:$A$240,"<"&T4+7,Summary!$A$2:$A$240,">="&IF(Dashboard!$B$3="",0,Dashboard!$B$3),Summary!$A$2:$A$240,"<"&IF(Dashboard!$B$4="",2958465,Dashboard!$B$4+1)),COUNTIFS(Summary!$E$2:$E$240,$A11,Summary!$D$2:$D$240,">="&T4,Summary!$D$2:$D$240,"<"&T4+7,Summary!$A$2:$A$240,">="&IF(Dashboard!$B$3="",0,Dashboard!$B$3),Summary!$A$2:$A$240,"<"&IF(Dashboard!$B$4="",2958465,Dashboard!$B$4+1)))) -> 0
A12: =IF(Settings!A11="","",Settings!A11) -> Drain tube blocked | B12: =IF($A12="","",IF(hm_basis="Call date",COUNTIFS(Summary!$E$2:$E$240,$A12,Summary!$A$2:$A$240,">="&B4,Summary!$A$2:$A$240,"<"&B4+7,Summary!$A$2:$A$240,">="&IF(Dashboard!$B$3="",0,Dashboard!$B$3),Summary!$A$2:$A$240,"<"&IF(Dashboard!$B$4="",2958465,Dashboard!$B$4+1)),COUNTIFS(Summary!$E$2:$E$240,$A12,Summary!$D$2:$D$240,">="&B4,Summary!$D$2:$D$240,"<"&B4+7,Summary!$A$2:$A$240,">="&IF(Dashboard!$B$3="",0,Dashboard!$B$3),Summary!$A$2:$A$240,"<"&IF(Dashboard!$B$4="",2958465,Dashboard!$B$4+1)))) -> 0 | C12: =IF($A12="","",IF(hm_basis="Call date",COUNTIFS(Summary!$E$2:$E$240,$A12,Summary!$A$2:$A$240,">="&C4,Summary!$A$2:$A$240,"<"&C4+7,Summary!$A$2:$A$240,">="&IF(Dashboard!$B$3="",0,Dashboard!$B$3),Summary!$A$2:$A$240,"<"&IF(Dashboard!$B$4="",2958465,Dashboard!$B$4+1)),COUNTIFS(Summary!$E$2:$E$240,$A12,Summary!$D$2:$D$240,">="&C4,Summary!$D$2:$D$240,"<"&C4+7,Summary!$A$2:$A$240,">="&IF(Dashboard!$B$3="",0,Dashboard!$B$3),Summary!$A$2:$A$240,"<"&IF(Dashboard!$B$4="",2958465,Dashboard!$B$4+1)))) -> 1 | D12: =IF($A12="","",IF(hm_basis="Call date",COUNTIFS(Summary!$E$2:$E$240,$A12,Summary!$A$2:$A$240,">="&D4,Summary!$A$2:$A$240,"<"&D4+7,Summary!$A$2:$A$240,">="&IF(Dashboard!$B$3="",0,Dashboard!$B$3),Summary!$A$2:$A$240,"<"&IF(Dashboard!$B$4="",2958465,Dashboard!$B$4+1)),COUNTIFS(Summary!$E$2:$E$240,$A12,Summary!$D$2:$D$240,">="&D4,Summary!$D$2:$D$240,"<"&D4+7,Summary!$A$2:$A$240,">="&IF(Dashboard!$B$3="",0,Dashboard!$B$3),Summary!$A$2:$A$240,"<"&IF(Dashboard!$B$4="",2958465,Dashboard!$B$4+1)))) -> 0 | E12: =IF($A12="","",IF(hm_basis="Call date",COUNTIFS(Summary!$E$2:$E$240,$A12,Summary!$A$2:$A$240,">="&E4,Summary!$A$2:$A$240,"<"&E4+7,Summary!$A$2:$A$240,">="&IF(Dashboard!$B$3="",0,Dashboard!$B$3),Summary!$A$2:$A$240,"<"&IF(Dashboard!$B$4="",2958465,Dashboard!$B$4+1)),COUNTIFS(Summary!$E$2:$E$240,$A12,Summary!$D$2:$D$240,">="&E4,Summary!$D$2:$D$240,"<"&E4+7,Summary!$A$2:$A$240,">="&IF(Dashboard!$B$3="",0,Dashboard!$B$3),Summary!$A$2:$A$240,"<"&IF(Dashboard!$B$4="",2958465,Dashboard!$B$4+1)))) -> 0 | F12: =IF($A12="","",IF(hm_basis="Call date",COUNTIFS(Summary!$E$2:$E$240,$A12,Summary!$A$2:$A$240,">="&F4,Summary!$A$2:$A$240,"<"&F4+7,Summary!$A$2:$A$240,">="&IF(Dashboard!$B$3="",0,Dashboard!$B$3),Summary!$A$2:$A$240,"<"&IF(Dashboard!$B$4="",2958465,Dashboard!$B$4+1)),COUNTIFS(Summary!$E$2:$E$240,$A12,Summary!$D$2:$D$240,">="&F4,Summary!$D$2:$D$240,"<"&F4+7,Summary!$A$2:$A$240,">="&IF(Dashboard!$B$3="",0,Dashboard!$B$3),Summary!$A$2:$A$240,"<"&IF(Dashboard!$B$4="",2958465,Dashboard!$B$4+1)))) -> 0 | G12: =IF($A12="","",IF(hm_basis="Call date",COUNTIFS(Summary!$E$2:$E$240,$A12,Summary!$A$2:$A$240,">="&G4,Summary!$A$2:$A$240,"<"&G4+7,Summary!$A$2:$A$240,">="&IF(Dashboard!$B$3="",0,Dashboard!$B$3),Summary!$A$2:$A$240,"<"&IF(Dashboard!$B$4="",2958465,Dashboard!$B$4+1)),COUNTIFS(Summary!$E$2:$E$240,$A12,Summary!$D$2:$D$240,">="&G4,Summary!$D$2:$D$240,"<"&G4+7,Summary!$A$2:$A$240,">="&IF(Dashboard!$B$3="",0,Dashboard!$B$3),Summary!$A$2:$A$240,"<"&IF(Dashboard!$B$4="",2958465,Dashboard!$B$4+1)))) -> 2 | H12: =IF($A12="","",IF(hm_basis="Call date",COUNTIFS(Summary!$E$2:$E$240,$A12,Summary!$A$2:$A$240,">="&H4,Summary!$A$2:$A$240,"<"&H4+7,Summary!$A$2:$A$240,">="&IF(Dashboard!$B$3="",0,Dashboard!$B$3),Summary!$A$2:$A$240,"<"&IF(Dashboard!$B$4="",2958465,Dashboard!$B$4+1)),COUNTIFS(Summary!$E$2:$E$240,$A12,Summary!$D$2:$D$240,">="&H4,Summary!$D$2:$D$240,"<"&H4+7,Summary!$A$2:$A$240,">="&IF(Dashboard!$B$3="",0,Dashboard!$B$3),Summary!$A$2:$A$240,"<"&IF(Dashboard!$B$4="",2958465,Dashboard!$B$4+1)))) -> 0 | I12: =IF($A12="","",IF(hm_basis="Call date",COUNTIFS(Summary!$E$2:$E$240,$A12,Summary!$A$2:$A$240,">="&I4,Summary!$A$2:$A$240,"<"&I4+7,Summary!$A$2:$A$240,">="&IF(Dashboard!$B$3="",0,Dashboard!$B$3),Summary!$A$2:$A$240,"<"&IF(Dashboard!$B$4="",2958465,Dashboard!$B$4+1)),COUNTIFS(Summary!$E$2:$E$240,$A12,Summary!$D$2:$D$240,">="&I4,Summary!$D$2:$D$240,"<"&I4+7,Summary!$A$2:$A$240,">="&IF(Dashboard!$B$3="",0,Dashboard!$B$3),Summary!$A$2:$A$240,"<"&IF(Dashboard!$B$4="",2958465,Dashboard!$B$4+1)))) -> 0 | ... T12: =IF($A12="","",IF(hm_basis="Call date",COUNTIFS(Summary!$E$2:$E$240,$A12,Summary!$A$2:$A$240,">="&T4,Summary!$A$2:$A$240,"<"&T4+7,Summary!$A$2:$A$240,">="&IF(Dashboard!$B$3="",0,Dashboard!$B$3),Summary!$A$2:$A$240,"<"&IF(Dashboard!$B$4="",2958465,Dashboard!$B$4+1)),COUNTIFS(Summary!$E$2:$E$240,$A12,Summary!$D$2:$D$240,">="&T4,Summary!$D$2:$D$240,"<"&T4+7,Summary!$A$2:$A$240,">="&IF(Dashboard!$B$3="",0,Dashboard!$B$3),Summary!$A$2:$A$240,"<"&IF(Dashboard!$B$4="",2958465,Dashboard!$B$4+1)))) -> 0
A13: =IF(Settings!A12="","",Settings!A12) -> Wrong / Loose wiring | B13: =IF($A13="","",IF(hm_basis="Call date",COUNTIFS(Summary!$E$2:$E$240,$A13,Summary!$A$2:$A$240,">="&B4,Summary!$A$2:$A$240,"<"&B4+7,Summary!$A$2:$A$240,">="&IF(Dashboard!$B$3="",0,Dashboard!$B$3),Summary!$A$2:$A$240,"<"&IF(Dashboard!$B$4="",2958465,Dashboard!$B$4+1)),COUNTIFS(Summary!$E$2:$E$240,$A13,Summary!$D$2:$D$240,">="&B4,Summary!$D$2:$D$240,"<"&B4+7,Summary!$A$2:$A$240,">="&IF(Dashboard!$B$3="",0,Dashboard!$B$3),Summary!$A$2:$A$240,"<"&IF(Dashboard!$B$4="",2958465,Dashboard!$B$4+1)))) -> 0 | C13: =IF($A13="","",IF(hm_basis="Call date",COUNTIFS(Summary!$E$2:$E$240,$A13,Summary!$A$2:$A$240,">="&C4,Summary!$A$2:$A$240,"<"&C4+7,Summary!$A$2:$A$240,">="&IF(Dashboard!$B$3="",0,Dashboard!$B$3),Summary!$A$2:$A$240,"<"&IF(Dashboard!$B$4="",2958465,Dashboard!$B$4+1)),COUNTIFS(Summary!$E$2:$E$240,$A13,Summary!$D$2:$D$240,">="&C4,Summary!$D$2:$D$240,"<"&C4+7,Summary!$A$2:$A$240,">="&IF(Dashboard!$B$3="",0,Dashboard!$B$3),Summary!$A$2:$A$240,"<"&IF(Dashboard!$B$4="",2958465,Dashboard!$B$4+1)))) -> 1 | D13: =IF($A13="","",IF(hm_basis="Call date",COUNTIFS(Summary!$E$2:$E$240,$A13,Summary!$A$2:$A$240,">="&D4,Summary!$A$2:$A$240,"<"&D4+7,Summary!$A$2:$A$240,">="&IF(Dashboard!$B$3="",0,Dashboard!$B$3),Summary!$A$2:$A$240,"<"&IF(Dashboard!$B$4="",2958465,Dashboard!$B$4+1)),COUNTIFS(Summary!$E$2:$E$240,$A13,Summary!$D$2:$D$240,">="&D4,Summary!$D$2:$D$240,"<"&D4+7,Summary!$A$2:$A$240,">="&IF(Dashboard!$B$3="",0,Dashboard!$B$3),Summary!$A$2:$A$240,"<"&IF(Dashboard!$B$4="",2958465,Dashboard!$B$4+1)))) -> 0 | E13: =IF($A13="","",IF(hm_basis="Call date",COUNTIFS(Summary!$E$2:$E$240,$A13,Summary!$A$2:$A$240,">="&E4,Summary!$A$2:$A$240,"<"&E4+7,Summary!$A$2:$A$240,">="&IF(Dashboard!$B$3="",0,Dashboard!$B$3),Summary!$A$2:$A$240,"<"&IF(Dashboard!$B$4="",2958465,Dashboard!$B$4+1)),COUNTIFS(Summary!$E$2:$E$240,$A13,Summary!$D$2:$D$240,">="&E4,Summary!$D$2:$D$240,"<"&E4+7,Summary!$A$2:$A$240,">="&IF(Dashboard!$B$3="",0,Dashboard!$B$3),Summary!$A$2:$A$240,"<"&IF(Dashboard!$B$4="",2958465,Dashboard!$B$4+1)))) -> 0 | F13: =IF($A13="","",IF(hm_basis="Call date",COUNTIFS(Summary!$E$2:$E$240,$A13,Summary!$A$2:$A$240,">="&F4,Summary!$A$2:$A$240,"<"&F4+7,Summary!$A$2:$A$240,">="&IF(Dashboard!$B$3="",0,Dashboard!$B$3),Summary!$A$2:$A$240,"<"&IF(Dashboard!$B$4="",2958465,Dashboard!$B$4+1)),COUNTIFS(Summary!$E$2:$E$240,$A13,Summary!$D$2:$D$240,">="&F4,Summary!$D$2:$D$240,"<"&F4+7,Summary!$A$2:$A$240,">="&IF(Dashboard!$B$3="",0,Dashboard!$B$3),Summary!$A$2:$A$240,"<"&IF(Dashboard!$B$4="",2958465,Dashboard!$B$4+1)))) -> 1 | G13: =IF($A13="","",IF(hm_basis="Call date",COUNTIFS(Summary!$E$2:$E$240,$A13,Summary!$A$2:$A$240,">="&G4,Summary!$A$2:$A$240,"<"&G4+7,Summary!$A$2:$A$240,">="&IF(Dashboard!$B$3="",0,Dashboard!$B$3),Summary!$A$2:$A$240,"<"&IF(Dashboard!$B$4="",2958465,Dashboard!$B$4+1)),COUNTIFS(Summary!$E$2:$E$240,$A13,Summary!$D$2:$D$240,">="&G4,Summary!$D$2:$D$240,"<"&G4+7,Summary!$A$2:$A$240,">="&IF(Dashboard!$B$3="",0,Dashboard!$B$3),Summary!$A$2:$A$240,"<"&IF(Dashboard!$B$4="",2958465,Dashboard!$B$4+1)))) -> 0 | H13: =IF($A13="","",IF(hm_basis="Call date",COUNTIFS(Summary!$E$2:$E$240,$A13,Summary!$A$2:$A$240,">="&H4,Summary!$A$2:$A$240,"<"&H4+7,Summary!$A$2:$A$240,">="&IF(Dashboard!$B$3="",0,Dashboard!$B$3),Summary!$A$2:$A$240,"<"&IF(Dashboard!$B$4="",2958465,Dashboard!$B$4+1)),COUNTIFS(Summary!$E$2:$E$240,$A13,Summary!$D$2:$D$240,">="&H4,Summary!$D$2:$D$240,"<"&H4+7,Summary!$A$2:$A$240,">="&IF(Dashboard!$B$3="",0,Dashboard!$B$3),Summary!$A$2:$A$240,"<"&IF(Dashboard!$B$4="",2958465,Dashboard!$B$4+1)))) -> 0 | I13: =IF($A13="","",IF(hm_basis="Call date",COUNTIFS(Summary!$E$2:$E$240,$A13,Summary!$A$2:$A$240,">="&I4,Summary!$A$2:$A$240,"<"&I4+7,Summary!$A$2:$A$240,">="&IF(Dashboard!$B$3="",0,Dashboard!$B$3),Summary!$A$2:$A$240,"<"&IF(Dashboard!$B$4="",2958465,Dashboard!$B$4+1)),COUNTIFS(Summary!$E$2:$E$240,$A13,Summary!$D$2:$D$240,">="&I4,Summary!$D$2:$D$240,"<"&I4+7,Summary!$A$2:$A$240,">="&IF(Dashboard!$B$3="",0,Dashboard!$B$3),Summary!$A$2:$A$240,"<"&IF(Dashboard!$B$4="",2958465,Dashboard!$B$4+1)))) -> 0 | ... T13: =IF($A13="","",IF(hm_basis="Call date",COUNTIFS(Summary!$E$2:$E$240,$A13,Summary!$A$2:$A$240,">="&T4,Summary!$A$2:$A$240,"<"&T4+7,Summary!$A$2:$A$240,">="&IF(Dashboard!$B$3="",0,Dashboard!$B$3),Summary!$A$2:$A$240,"<"&IF(Dashboard!$B$4="",2958465,Dashboard!$B$4+1)),COUNTIFS(Summary!$E$2:$E$240,$A13,Summary!$D$2:$D$240,">="&T4,Summary!$D$2:$D$240,"<"&T4+7,Summary!$A$2:$A$240,">="&IF(Dashboard!$B$3="",0,Dashboard!$B$3),Summary!$A$2:$A$240,"<"&IF(Dashboard!$B$4="",2958465,Dashboard!$B$4+1)))) -> 0
A14: =IF(Settings!A13="","",Settings!A13) -> Communication problem | B14: =IF($A14="","",IF(hm_basis="Call date",COUNTIFS(Summary!$E$2:$E$240,$A14,Summary!$A$2:$A$240,">="&B4,Summary!$A$2:$A$240,"<"&B4+7,Summary!$A$2:$A$240,">="&IF(Dashboard!$B$3="",0,Dashboard!$B$3),Summary!$A$2:$A$240,"<"&IF(Dashboard!$B$4="",2958465,Dashboard!$B$4+1)),COUNTIFS(Summary!$E$2:$E$240,$A14,Summary!$D$2:$D$240,">="&B4,Summary!$D$2:$D$240,"<"&B4+7,Summary!$A$2:$A$240,">="&IF(Dashboard!$B$3="",0,Dashboard!$B$3),Summary!$A$2:$A$240,"<"&IF(Dashboard!$B$4="",2958465,Dashboard!$B$4+1)))) -> 0 | C14: =IF($A14="","",IF(hm_basis="Call date",COUNTIFS(Summary!$E$2:$E$240,$A14,Summary!$A$2:$A$240,">="&C4,Summary!$A$2:$A$240,"<"&C4+7,Summary!$A$2:$A$240,">="&IF(Dashboard!$B$3="",0,Dashboard!$B$3),Summary!$A$2:$A$240,"<"&IF(Dashboard!$B$4="",2958465,Dashboard!$B$4+1)),COUNTIFS(Summary!$E$2:$E$240,$A14,Summary!$D$2:$D$240,">="&C4,Summary!$D$2:$D$240,"<"&C4+7,Summary!$A$2:$A$240,">="&IF(Dashboard!$B$3="",0,Dashboard!$B$3),Summary!$A$2:$A$240,"<"&IF(Dashboard!$B$4="",2958465,Dashboard!$B$4+1)))) -> 1 | D14: =IF($A14="","",IF(hm_basis="Call date",COUNTIFS(Summary!$E$2:$E$240,$A14,Summary!$A$2:$A$240,">="&D4,Summary!$A$2:$A$240,"<"&D4+7,Summary!$A$2:$A$240,">="&IF(Dashboard!$B$3="",0,Dashboard!$B$3),Summary!$A$2:$A$240,"<"&IF(Dashboard!$B$4="",2958465,Dashboard!$B$4+1)),COUNTIFS(Summary!$E$2:$E$240,$A14,Summary!$D$2:$D$240,">="&D4,Summary!$D$2:$D$240,"<"&D4+7,Summary!$A$2:$A$240,">="&IF(Dashboard!$B$3="",0,Dashboard!$B$3),Summary!$A$2:$A$240,"<"&IF(Dashboard!$B$4="",2958465,Dashboard!$B$4+1)))) -> 2 | E14: =IF($A14="","",IF(hm_basis="Call date",COUNTIFS(Summary!$E$2:$E$240,$A14,Summary!$A$2:$A$240,">="&E4,Summary!$A$2:$A$240,"<"&E4+7,Summary!$A$2:$A$240,">="&IF(Dashboard!$B$3="",0,Dashboard!$B$3),Summary!$A$2:$A$240,"<"&IF(Dashboard!$B$4="",2958465,Dashboard!$B$4+1)),COUNTIFS(Summary!$E$2:$E$240,$A14,Summary!$D$2:$D$240,">="&E4,Summary!$D$2:$D$240,"<"&E4+7,Summary!$A$2:$A$240,">="&IF(Dashboard!$B$3="",0,Dashboard!$B$3),Summary!$A$2:$A$240,"<"&IF(Dashboard!$B$4="",2958465,Dashboard!$B$4+1)))) -> 0 | F14: =IF($A14="","",IF(hm_basis="Call date",COUNTIFS(Summary!$E$2:$E$240,$A14,Summary!$A$2:$A$240,">="&F4,Summary!$A$2:$A$240,"<"&F4+7,Summary!$A$2:$A$240,">="&IF(Dashboard!$B$3="",0,Dashboard!$B$3),Summary!$A$2:$A$240,"<"&IF(Dashboard!$B$4="",2958465,Dashboard!$B$4+1)),COUNTIFS(Summary!$E$2:$E$240,$A14,Summary!$D$2:$D$240,">="&F4,Summary!$D$2:$D$240,"<"&F4+7,Summary!$A$2:$A$240,">="&IF(Dashboard!$B$3="",0,Dashboard!$B$3),Summary!$A$2:$A$240,"<"&IF(Dashboard!$B$4="",2958465,Dashboard!$B$4+1)))) -> 1 | G14: =IF($A14="","",IF(hm_basis="Call date",COUNTIFS(Summary!$E$2:$E$240,$A14,Summary!$A$2:$A$240,">="&G4,Summary!$A$2:$A$240,"<"&G4+7,Summary!$A$2:$A$240,">="&IF(Dashboard!$B$3="",0,Dashboard!$B$3),Summary!$A$2:$A$240,"<"&IF(Dashboard!$B$4="",2958465,Dashboard!$B$4+1)),COUNTIFS(Summary!$E$2:$E$240,$A14,Summary!$D$2:$D$240,">="&G4,Summary!$D$2:$D$240,"<"&G4+7,Summary!$A$2:$A$240,">="&IF(Dashboard!$B$3="",0,Dashboard!$B$3),Summary!$A$2:$A$240,"<"&IF(Dashboard!$B$4="",2958465,Dashboard!$B$4+1)))) -> 0 | H14: =IF($A14="","",IF(hm_basis="Call date",COUNTIFS(Summary!$E$2:$E$240,$A14,Summary!$A$2:$A$240,">="&H4,Summary!$A$2:$A$240,"<"&H4+7,Summary!$A$2:$A$240,">="&IF(Dashboard!$B$3="",0,Dashboard!$B$3),Summary!$A$2:$A$240,"<"&IF(Dashboard!$B$4="",2958465,Dashboard!$B$4+1)),COUNTIFS(Summary!$E$2:$E$240,$A14,Summary!$D$2:$D$240,">="&H4,Summary!$D$2:$D$240,"<"&H4+7,Summary!$A$2:$A$240,">="&IF(Dashboard!$B$3="",0,Dashboard!$B$3),Summary!$A$2:$A$240,"<"&IF(Dashboard!$B$4="",2958465,Dashboard!$B$4+1)))) -> 0 | I14: =IF($A14="","",IF(hm_basis="Call date",COUNTIFS(Summary!$E$2:$E$240,$A14,Summary!$A$2:$A$240,">="&I4,Summary!$A$2:$A$240,"<"&I4+7,Summary!$A$2:$A$240,">="&IF(Dashboard!$B$3="",0,Dashboard!$B$3),Summary!$A$2:$A$240,"<"&IF(Dashboard!$B$4="",2958465,Dashboard!$B$4+1)),COUNTIFS(Summary!$E$2:$E$240,$A14,Summary!$D$2:$D$240,">="&I4,Summary!$D$2:$D$240,"<"&I4+7,Summary!$A$2:$A$240,">="&IF(Dashboard!$B$3="",0,Dashboard!$B$3),Summary!$A$2:$A$240,"<"&IF(Dashboard!$B$4="",2958465,Dashboard!$B$4+1)))) -> 0 | ... T14: =IF($A14="","",IF(hm_basis="Call date",COUNTIFS(Summary!$E$2:$E$240,$A14,Summary!$A$2:$A$240,">="&T4,Summary!$A$2:$A$240,"<"&T4+7,Summary!$A$2:$A$240,">="&IF(Dashboard!$B$3="",0,Dashboard!$B$3),Summary!$A$2:$A$240,"<"&IF(Dashboard!$B$4="",2958465,Dashboard!$B$4+1)),COUNTIFS(Summary!$E$2:$E$240,$A14,Summary!$D$2:$D$240,">="&T4,Summary!$D$2:$D$240,"<"&T4+7,Summary!$A$2:$A$240,">="&IF(Dashboard!$B$3="",0,Dashboard!$B$3),Summary!$A$2:$A$240,"<"&IF(Dashboard!$B$4="",2958465,Dashboard!$B$4+1)))) -> 0
A15: =IF(Settings!A14="","",Settings!A14) -> High Store RH | B15: =IF($A15="","",IF(hm_basis="Call date",COUNTIFS(Summary!$E$2:$E$240,$A15,Summary!$A$2:$A$240,">="&B4,Summary!$A$2:$A$240,"<"&B4+7,Summary!$A$2:$A$240,">="&IF(Dashboard!$B$3="",0,Dashboard!$B$3),Summary!$A$2:$A$240,"<"&IF(Dashboard!$B$4="",2958465,Dashboard!$B$4+1)),COUNTIFS(Summary!$E$2:$E$240,$A15,Summary!$D$2:$D$240,">="&B4,Summary!$D$2:$D$240,"<"&B4+7,Summary!$A$2:$A$240,">="&IF(Dashboard!$B$3="",0,Dashboard!$B$3),Summary!$A$2:$A$240,"<"&IF(Dashboard!$B$4="",2958465,Dashboard!$B$4+1)))) -> 0 | C15: =IF($A15="","",IF(hm_basis="Call date",COUNTIFS(Summary!$E$2:$E$240,$A15,Summary!$A$2:$A$240,">="&C4,Summary!$A$2:$A$240,"<"&C4+7,Summary!$A$2:$A$240,">="&IF(Dashboard!$B$3="",0,Dashboard!$B$3),Summary!$A$2:$A$240,"<"&IF(Dashboard!$B$4="",2958465,Dashboard!$B$4+1)),COUNTIFS(Summary!$E$2:$E$240,$A15,Summary!$D$2:$D$240,">="&C4,Summary!$D$2:$D$240,"<"&C4+7,Summary!$A$2:$A$240,">="&IF(Dashboard!$B$3="",0,Dashboard!$B$3),Summary!$A$2:$A$240,"<"&IF(Dashboard!$B$4="",2958465,Dashboard!$B$4+1)))) -> 1 | D15: =IF($A15="","",IF(hm_basis="Call date",COUNTIFS(Summary!$E$2:$E$240,$A15,Summary!$A$2:$A$240,">="&D4,Summary!$A$2:$A$240,"<"&D4+7,Summary!$A$2:$A$240,">="&IF(Dashboard!$B$3="",0,Dashboard!$B$3),Summary!$A$2:$A$240,"<"&IF(Dashboard!$B$4="",2958465,Dashboard!$B$4+1)),COUNTIFS(Summary!$E$2:$E$240,$A15,Summary!$D$2:$D$240,">="&D4,Summary!$D$2:$D$240,"<"&D4+7,Summary!$A$2:$A$240,">="&IF(Dashboard!$B$3="",0,Dashboard!$B$3),Summary!$A$2:$A$240,"<"&IF(Dashboard!$B$4="",2958465,Dashboard!$B$4+1)))) -> 0 | E15: =IF($A15="","",IF(hm_basis="Call date",COUNTIFS(Summary!$E$2:$E$240,$A15,Summary!$A$2:$A$240,">="&E4,Summary!$A$2:$A$240,"<"&E4+7,Summary!$A$2:$A$240,">="&IF(Dashboard!$B$3="",0,Dashboard!$B$3),Summary!$A$2:$A$240,"<"&IF(Dashboard!$B$4="",2958465,Dashboard!$B$4+1)),COUNTIFS(Summary!$E$2:$E$240,$A15,Summary!$D$2:$D$240,">="&E4,Summary!$D$2:$D$240,"<"&E4+7,Summary!$A$2:$A$240,">="&IF(Dashboard!$B$3="",0,Dashboard!$B$3),Summary!$A$2:$A$240,"<"&IF(Dashboard!$B$4="",2958465,Dashboard!$B$4+1)))) -> 1 | F15: =IF($A15="","",IF(hm_basis="Call date",COUNTIFS(Summary!$E$2:$E$240,$A15,Summary!$A$2:$A$240,">="&F4,Summary!$A$2:$A$240,"<"&F4+7,Summary!$A$2:$A$240,">="&IF(Dashboard!$B$3="",0,Dashboard!$B$3),Summary!$A$2:$A$240,"<"&IF(Dashboard!$B$4="",2958465,Dashboard!$B$4+1)),COUNTIFS(Summary!$E$2:$E$240,$A15,Summary!$D$2:$D$240,">="&F4,Summary!$D$2:$D$240,"<"&F4+7,Summary!$A$2:$A$240,">="&IF(Dashboard!$B$3="",0,Dashboard!$B$3),Summary!$A$2:$A$240,"<"&IF(Dashboard!$B$4="",2958465,Dashboard!$B$4+1)))) -> 1 | G15: =IF($A15="","",IF(hm_basis="Call date",COUNTIFS(Summary!$E$2:$E$240,$A15,Summary!$A$2:$A$240,">="&G4,Summary!$A$2:$A$240,"<"&G4+7,Summary!$A$2:$A$240,">="&IF(Dashboard!$B$3="",0,Dashboard!$B$3),Summary!$A$2:$A$240,"<"&IF(Dashboard!$B$4="",2958465,Dashboard!$B$4+1)),COUNTIFS(Summary!$E$2:$E$240,$A15,Summary!$D$2:$D$240,">="&G4,Summary!$D$2:$D$240,"<"&G4+7,Summary!$A$2:$A$240,">="&IF(Dashboard!$B$3="",0,Dashboard!$B$3),Summary!$A$2:$A$240,"<"&IF(Dashboard!$B$4="",2958465,Dashboard!$B$4+1)))) -> 5 | H15: =IF($A15="","",IF(hm_basis="Call date",COUNTIFS(Summary!$E$2:$E$240,$A15,Summary!$A$2:$A$240,">="&H4,Summary!$A$2:$A$240,"<"&H4+7,Summary!$A$2:$A$240,">="&IF(Dashboard!$B$3="",0,Dashboard!$B$3),Summary!$A$2:$A$240,"<"&IF(Dashboard!$B$4="",2958465,Dashboard!$B$4+1)),COUNTIFS(Summary!$E$2:$E$240,$A15,Summary!$D$2:$D$240,">="&H4,Summary!$D$2:$D$240,"<"&H4+7,Summary!$A$2:$A$240,">="&IF(Dashboard!$B$3="",0,Dashboard!$B$3),Summary!$A$2:$A$240,"<"&IF(Dashboard!$B$4="",2958465,Dashboard!$B$4+1)))) -> 1 | I15: =IF($A15="","",IF(hm_basis="Call date",COUNTIFS(Summary!$E$2:$E$240,$A15,Summary!$A$2:$A$240,">="&I4,Summary!$A$2:$A$240,"<"&I4+7,Summary!$A$2:$A$240,">="&IF(Dashboard!$B$3="",0,Dashboard!$B$3),Summary!$A$2:$A$240,"<"&IF(Dashboard!$B$4="",2958465,Dashboard!$B$4+1)),COUNTIFS(Summary!$E$2:$E$240,$A15,Summary!$D$2:$D$240,">="&I4,Summary!$D$2:$D$240,"<"&I4+7,Summary!$A$2:$A$240,">="&IF(Dashboard!$B$3="",0,Dashboard!$B$3),Summary!$A$2:$A$240,"<"&IF(Dashboard!$B$4="",2958465,Dashboard!$B$4+1)))) -> 0 | ... T15: =IF($A15="","",IF(hm_basis="Call date",COUNTIFS(Summary!$E$2:$E$240,$A15,Summary!$A$2:$A$240,">="&T4,Summary!$A$2:$A$240,"<"&T4+7,Summary!$A$2:$A$240,">="&IF(Dashboard!$B$3="",0,Dashboard!$B$3),Summary!$A$2:$A$240,"<"&IF(Dashboard!$B$4="",2958465,Dashboard!$B$4+1)),COUNTIFS(Summary!$E$2:$E$240,$A15,Summary!$D$2:$D$240,">="&T4,Summary!$D$2:$D$240,"<"&T4+7,Summary!$A$2:$A$240,">="&IF(Dashboard!$B$3="",0,Dashboard!$B$3),Summary!$A$2:$A$240,"<"&IF(Dashboard!$B$4="",2958465,Dashboard!$B$4+1)))) -> 0
