Workbook
Name ch1_cats: OFFSET(Calc_Charts!$A$66,0,0,MAX(1,COUNTIF(Calc_Charts!$B$66:$B$90,">0")),1)
Name ch1_vals: OFFSET(Calc_Charts!$B$66,0,0,MAX(1,COUNTIF(Calc_Charts!$B$66:$B$90,">0")),1)
Name ch3_cats: OFFSET(Calc_Charts!$A$96,0,0,MAX(1,COUNTIF(Calc_Charts!$B$96:$B$120,">0")),1)
Name ch3_vals: OFFSET(Calc_Charts!$B$96,0,0,MAX(1,COUNTIF(Calc_Charts!$B$96:$B$120,">0")),1)
Name ch5_after: OFFSET(Calc_Charts!$B$126,0,0,MAX(1,COUNTIF(Calc_Charts!$D$126:$D$150,">0")),1)
Name ch5_before: OFFSET(Calc_Charts!$C$126,0,0,MAX(1,COUNTIF(Calc_Charts!$D$126:$D$150,">0")),1)
Name ch5_cats: OFFSET(Calc_Charts!$A$126,0,0,MAX(1,COUNTIF(Calc_Charts!$D$126:$D$150,">0")),1)
Name ch5_seg01: OFFSET(Calc_Charts!$B$156,0,0,MAX(1,COUNTIF(Calc_Charts!$D$126:$D$150,">0")),1)
Name ch5_seg02: OFFSET(Calc_Charts!$C$156,0,0,MAX(1,COUNTIF(Calc_Charts!$D$126:$D$150,">0")),1)
Name ch5_seg03: OFFSET(Calc_Charts!$D$156,0,0,MAX(1,COUNTIF(Calc_Charts!$D$126:$D$150,">0")),1)
Name ch5_seg04: OFFSET(Calc_Charts!$E$156,0,0,MAX(1,COUNTIF(Calc_Charts!$D$126:$D$150,">0")),1)
Name ch5_seg05: OFFSET(Calc_Charts!$F$156,0,0,MAX(1,COUNTIF(Calc_Charts!$D$126:$D$150,">0")),1)
Name ch5_seg06: OFFSET(Calc_Charts!$G$156,0,0,MAX(1,COUNTIF(Calc_Charts!$D$126:$D$150,">0")),1)
Name ch5_seg07: OFFSET(Calc_Charts!$H$156,0,0,MAX(1,COUNTIF(Calc_Charts!$D$126:$D$150,">0")),1)
Name ch5_seg08: OFFSET(Calc_Charts!$I$156,0,0,MAX(1,COUNTIF(Calc_Charts!$D$126:$D$150,">0")),1)
Name ch5_seg09: OFFSET(Calc_Charts!$J$156,0,0,MAX(1,COUNTIF(Calc_Charts!$D$126:$D$150,">0")),1)
Name ch5_seg10: OFFSET(Calc_Charts!$K$156,0,0,MAX(1,COUNTIF(Calc_Charts!$D$126:$D$150,">0")),1)
Name ch5_seg11: OFFSET(Calc_Charts!$L$156,0,0,MAX(1,COUNTIF(Calc_Charts!$D$126:$D$150,">0")),1)
Name ch5_seg12: OFFSET(Calc_Charts!$M$156,0,0,MAX(1,COUNTIF(Calc_Charts!$D$126:$D$150,">0")),1)
Name ch5_seg13: OFFSET(Calc_Charts!$N$156,0,0,MAX(1,COUNTIF(Calc_Charts!$D$126:$D$150,">0")),1)
Name ch5_seg14: OFFSET(Calc_Charts!$O$156,0,0,MAX(1,COUNTIF(Calc_Charts!$D$126:$D$150,">0")),1)
Name ch5_seg15: OFFSET(Calc_Charts!$P$156,0,0,MAX(1,COUNTIF(Calc_Charts!$D$126:$D$150,">0")),1)
Name ch5_seg16: OFFSET(Calc_Charts!$Q$156,0,0,MAX(1,COUNTIF(Calc_Charts!$D$126:$D$150,">0")),1)
Name ch5_seg17: OFFSET(Calc_Charts!$R$156,0,0,MAX(1,COUNTIF(Calc_Charts!$D$126:$D$150,">0")),1)
Name ch5_seg18: OFFSET(Calc_Charts!$S$156,0,0,MAX(1,COUNTIF(Calc_Charts!$D$126:$D$150,">0")),1)
Name ch5_seg19: OFFSET(Calc_Charts!$T$156,0,0,MAX(1,COUNTIF(Calc_Charts!$D$126:$D$150,">0")),1)
Name ch5_seg20: OFFSET(Calc_Charts!$U$156,0,0,MAX(1,COUNTIF(Calc_Charts!$D$126:$D$150,">0")),1)
Name ch5_seg21: OFFSET(Calc_Charts!$V$156,0,0,MAX(1,COUNTIF(Calc_Charts!$D$126:$D$150,">0")),1)
Name ch5_seg22: OFFSET(Calc_Charts!$W$156,0,0,MAX(1,COUNTIF(Calc_Charts!$D$126:$D$150,">0")),1)
Name ch5_seg23: OFFSET(Calc_Charts!$X$156,0,0,MAX(1,COUNTIF(Calc_Charts!$D$126:$D$150,">0")),1)
Name ch5_seg24: OFFSET(Calc_Charts!$Y$156,0,0,MAX(1,COUNTIF(Calc_Charts!$D$126:$D$150,">0")),1)
Name ch5_seg25: OFFSET(Calc_Charts!$Z$156,0,0,MAX(1,COUNTIF(Calc_Charts!$D$126:$D$150,">0")),1)
Name ch5_total: OFFSET(Calc_Charts!$D$126,0,0,MAX(1,COUNTIF(Calc_Charts!$D$126:$D$150,">0")),1)
Name ch6_cats: Calc_Charts!$A$244:$A$249
Name ch6_vals: Calc_Charts!$B$244:$B$249
Name ch7_after: OFFSET(Calc_Charts!$B$359,0,0,MAX(1,COUNTIF(Calc_Charts!$D$359:$D$383,">0")),1)
Name ch7_before: OFFSET(Calc_Charts!$C$359,0,0,MAX(1,COUNTIF(Calc_Charts!$D$359:$D$383,">0")),1)
Name ch7_cats: OFFSET(Calc_Charts!$A$359,0,0,MAX(1,COUNTIF(Calc_Charts!$D$359:$D$383,">0")),1)
Name ch7_prefix: Calc_Charts!$B$269
Name ch7_seg01: OFFSET(Calc_Charts!$B$387,0,0,MAX(1,COUNTIF(Calc_Charts!$D$359:$D$383,">0")),1)
Name ch7_seg02: OFFSET(Calc_Charts!$C$387,0,0,MAX(1,COUNTIF(Calc_Charts!$D$359:$D$383,">0")),1)
Name ch7_seg03: OFFSET(Calc_Charts!$D$387,0,0,MAX(1,COUNTIF(Calc_Charts!$D$359:$D$383,">0")),1)
Name ch7_seg04: OFFSET(Calc_Charts!$E$387,0,0,MAX(1,COUNTIF(Calc_Charts!$D$359:$D$383,">0")),1)
Name ch7_seg05: OFFSET(Calc_Charts!$F$387,0,0,MAX(1,COUNTIF(Calc_Charts!$D$359:$D$383,">0")),1)
Name ch7_seg06: OFFSET(Calc_Charts!$G$387,0,0,MAX(1,COUNTIF(Calc_Charts!$D$359:$D$383,">0")),1)
Name ch7_seg07: OFFSET(Calc_Charts!$H$387,0,0,MAX(1,COUNTIF(Calc_Charts!$D$359:$D$383,">0")),1)
Name ch7_seg08: OFFSET(Calc_Charts!$I$387,0,0,MAX(1,COUNTIF(Calc_Charts!$D$359:$D$383,">0")),1)
Name ch7_seg09: OFFSET(Calc_Charts!$J$387,0,0,MAX(1,COUNTIF(Calc_Charts!$D$359:$D$383,">0")),1)
Name ch7_seg10: OFFSET(Calc_Charts!$K$387,0,0,MAX(1,COUNTIF(Calc_Charts!$D$359:$D$383,">0")),1)
Name ch7_seg11: OFFSET(Calc_Charts!$L$387,0,0,MAX(1,COUNTIF(Calc_Charts!$D$359:$D$383,">0")),1)
Name ch7_seg12: OFFSET(Calc_Charts!$M$387,0,0,MAX(1,COUNTIF(Calc_Charts!$D$359:$D$383,">0")),1)
Name ch7_seg13: OFFSET(Calc_Charts!$N$387,0,0,MAX(1,COUNTIF(Calc_Charts!$D$359:$D$383,">0")),1)
Name ch7_seg14: OFFSET(Calc_Charts!$O$387,0,0,MAX(1,COUNTIF(Calc_Charts!$D$359:$D$383,">0")),1)
Name ch7_seg15: OFFSET(Calc_Charts!$P$387,0,0,MAX(1,COUNTIF(Calc_Charts!$D$359:$D$383,">0")),1)
Name ch7_seg16: OFFSET(Calc_Charts!$Q$387,0,0,MAX(1,COUNTIF(Calc_Charts!$D$359:$D$383,">0")),1)
Name ch7_seg17: OFFSET(Calc_Charts!$R$387,0,0,MAX(1,COUNTIF(Calc_Charts!$D$359:$D$383,">0")),1)
Name ch7_seg18: OFFSET(Calc_Charts!$S$387,0,0,MAX(1,COUNTIF(Calc_Charts!$D$359:$D$383,">0")),1)
Name ch7_seg19: OFFSET(Calc_Charts!$T$387,0,0,MAX(1,COUNTIF(Calc_Charts!$D$359:$D$383,">0")),1)
Name ch7_seg20: OFFSET(Calc_Charts!$U$387,0,0,MAX(1,COUNTIF(Calc_Charts!$D$359:$D$383,">0")),1)
Name ch7_seg21: OFFSET(Calc_Charts!$V$387,0,0,MAX(1,COUNTIF(Calc_Charts!$D$359:$D$383,">0")),1)

Sheet README
A1: DG-template workbook guide
A3: Purpose | B3: Tracks service-call root causes and feeds six dashboard charts with timeline filtering, zero-bar hiding, sorted rankings, and stable chart colors.
A5: Weekly update workflow | B5: Paste CRM rows into Raw Data, classify lines in Summary, review Data Checks, then use Dashboard. From/To blanks mean all data.
A7: Color legend | B7: Blue text = user input; black = formula; gray fill = helper/sort columns; yellow fill = dashboard timeline inputs.
A9: Limit | B9: Value | C9: Settings name
A10: Max Summary rows | B10: =Settings!B65 -> 240 | C10: set_maxSummaryRow
A11: Max Raw rows | B11: =Settings!B66 -> 400 | C11: set_maxRawRow
A12: Max causes | B12: =Settings!B67 -> 80 | C12: set_maxCauses
A13: Weeks shown | B13: =Settings!B68 -> 20 | C13: set_weeksShown
A14: Tiebreak divisor | B14: =Settings!B69 -> 100000 | C14: set_tiebreakDivisor
A17: Calc table | B17: Description
A18: T1 | B18: Cause totals filtered by Dashboard date window.
A19: T2 | B19: Unique group totals with dedup helper and sort helpers.
A20: T3 | B20: Ranked groups by total; feeds Chart 1 names.
A21: T4 | B21: Ranked groups by after-clean count; feeds Chart 3 names.
A22: T5 | B22: Chart 5 stacked after/before feed.
A23: T6 | B23: Chart 5 diagonal matrix for stable rank colors.
A24: T7 | B24: Formula-driven week labels and total-label series.
A25: T8 | B25: Counts rollup by group.
A26: T9 | B26: Case serial-prefix counts for Chart 6.
A27: T10 | B27: Dynamic chart title cells.
A29: Phase 3 charts
A30: Charts 7-9 | B30: Per-nomenclature after-vs-before clean point charts for RLN3MA, RLN2MA, and RMN4MA. Add another prefix by copying one T-block, cloning the chN_* names, and cloning Chart 5.
A31: Prefix correction | B31: Settings T-S3 corrected RMN2MA to RMN4MA after confirming RMN2MA has no serial matches and RMN4MA has matches.

Sheet Dashboard
A1: DG Service-Call Dashboard
A3: From | B3: 46174
A4: To | B4: 46218
A5: Period | B5: =Calc_Charts!$B$262 -> Jun 1 to Jul 15
A6: Checks needing review | B6: =COUNTIF('Data Checks'!$C:$C,"Review") -> 1

Sheet Summary
A1: Edit blue-input columns only: Work Order, Root Cause, and Notes. Formula columns classify/store/date/after-clean status.
A2: Summary - one line per root-cause pick
A3: Visible classified lines: | C3: =SUBTOTAL(103,$E$5:$E$241) -> 38 | E3: Filter Root Cause to read this count.
A4: Call Date | B4: Work Order | C4: Store | D4: Commission Date | E4: Root Cause | F4: Notes | G4: After Clean Point | H4: Case Serial (from Raw) | I4: Column1
A5: =IFERROR(INDEX('Raw Data'!$D$5:$D$400,MATCH($B5,'Raw Data'!$H$5:$H$400,0)),"") -> 46094.393 | B5: WO-0532764 | C5: =IFERROR(TRIM(INDEX('Raw Data'!$J$5:$J$400,MATCH($B5,'Raw Data'!$H$5:$H$400,0))),"") -> Dollar General #22515 | D5: =IFERROR(INDEX('Store List'!$B$4:$B$300,MATCH($C5,'Store List'!$A$4:$A$300,0)),"") -> 46090 | E5: Door Torque | F5: Tech found door torque issue and adjusted it | G5: =IF($E5="","",IFERROR(IF(OR(NOT(ISNUMBER($D5)),NOT(ISNUMBER(INDEX(Settings!$E$4:$E$80,MATCH($E5,Settings!$A$4:$A$80,0))))),"No",IF($D5>INDEX(Settings!$E$4:$E$80,MATCH($E5,Settings!$A$4:$A$80,0)),"Yes","No")),"")) -> No | H5: =IFERROR(TRIM(INDEX('Raw Data'!$S$5:$S$400,MATCH($B5,'Raw Data'!$H$5:$H$400,0))),"") -> RMN5MA/MY26B013859
A6: =IFERROR(INDEX('Raw Data'!$D$5:$D$400,MATCH($B6,'Raw Data'!$H$5:$H$400,0)),"") -> 46094.393 | B6: WO-0532764 | C6: =IFERROR(TRIM(INDEX('Raw Data'!$J$5:$J$400,MATCH($B6,'Raw Data'!$H$5:$H$400,0))),"") -> Dollar General #22515 | D6: =IFERROR(INDEX('Store List'!$B$4:$B$300,MATCH($C6,'Store List'!$A$4:$A$300,0)),"") -> 46090 | E6: Drain tube blocked | G6: =IF($E6="","",IFERROR(IF(OR(NOT(ISNUMBER($D6)),NOT(ISNUMBER(INDEX(Settings!$E$4:$E$80,MATCH($E6,Settings!$A$4:$A$80,0))))),"No",IF($D6>INDEX(Settings!$E$4:$E$80,MATCH($E6,Settings!$A$4:$A$80,0)),"Yes","No")),"")) -> No | H6: =IFERROR(TRIM(INDEX('Raw Data'!$S$5:$S$400,MATCH($B6,'Raw Data'!$H$5:$H$400,0))),"") -> RMN5MA/MY26B013859
A7: =IFERROR(INDEX('Raw Data'!$D$5:$D$400,MATCH($B7,'Raw Data'!$H$5:$H$400,0)),"") -> 46092.344 | B7: WO-0531272 | C7: =IFERROR(TRIM(INDEX('Raw Data'!$J$5:$J$400,MATCH($B7,'Raw Data'!$H$5:$H$400,0))),"") -> Dollar General #21606 | D7: =IFERROR(INDEX('Store List'!$B$4:$B$300,MATCH($C7,'Store List'!$A$4:$A$300,0)),"") -> 46084 | E7: Drain tube blocked | G7: =IF($E7="","",IFERROR(IF(OR(NOT(ISNUMBER($D7)),NOT(ISNUMBER(INDEX(Settings!$E$4:$E$80,MATCH($E7,Settings!$A$4:$A$80,0))))),"No",IF($D7>INDEX(Settings!$E$4:$E$80,MATCH($E7,Settings!$A$4:$A$80,0)),"Yes","No")),"")) -> No | H7: =IFERROR(TRIM(INDEX('Raw Data'!$S$5:$S$400,MATCH($B7,'Raw Data'!$H$5:$H$400,0))),"") -> RMN5MA/MY26B013853
A8: =IFERROR(INDEX('Raw Data'!$D$5:$D$400,MATCH($B8,'Raw Data'!$H$5:$H$400,0)),"") -> 46092.344 | B8: WO-0531272 | C8: =IFERROR(TRIM(INDEX('Raw Data'!$J$5:$J$400,MATCH($B8,'Raw Data'!$H$5:$H$400,0))),"") -> Dollar General #21606 | D8: =IFERROR(INDEX('Store List'!$B$4:$B$300,MATCH($C8,'Store List'!$A$4:$A$300,0)),"") -> 46084 | E8: High Store RH | G8: =IF($E8="","",IFERROR(IF(OR(NOT(ISNUMBER($D8)),NOT(ISNUMBER(INDEX(Settings!$E$4:$E$80,MATCH($E8,Settings!$A$4:$A$80,0))))),"No",IF($D8>INDEX(Settings!$E$4:$E$80,MATCH($E8,Settings!$A$4:$A$80,0)),"Yes","No")),"")) -> No | H8: =IFERROR(TRIM(INDEX('Raw Data'!$S$5:$S$400,MATCH($B8,'Raw Data'!$H$5:$H$400,0))),"") -> RMN5MA/MY26B013853
A9: =IFERROR(INDEX('Raw Data'!$D$5:$D$400,MATCH($B9,'Raw Data'!$H$5:$H$400,0)),"") -> 46102.389 | B9: WO-0536941 | C9: =IFERROR(TRIM(INDEX('Raw Data'!$J$5:$J$400,MATCH($B9,'Raw Data'!$H$5:$H$400,0))),"") -> Dollar General #20582 | D9: =IFERROR(INDEX('Store List'!$B$4:$B$300,MATCH($C9,'Store List'!$A$4:$A$300,0)),"") -> 46098 | E9: Ref. leak/ Low charge | G9: =IF($E9="","",IFERROR(IF(OR(NOT(ISNUMBER($D9)),NOT(ISNUMBER(INDEX(Settings!$E$4:$E$80,MATCH($E9,Settings!$A$4:$A$80,0))))),"No",IF($D9>INDEX(Settings!$E$4:$E$80,MATCH($E9,Settings!$A$4:$A$80,0)),"Yes","No")),"")) -> No | H9: =IFERROR(TRIM(INDEX('Raw Data'!$S$5:$S$400,MATCH($B9,'Raw Data'!$H$5:$H$400,0))),"") -> RLN3MA/MY26B014956, LEFT ~ RLN2MA/ MY26B016476, LEFT
A10: =IFERROR(INDEX('Raw Data'!$D$5:$D$400,MATCH($B10,'Raw Data'!$H$5:$H$400,0)),"") -> 46102.389 | B10: WO-0536941 | C10: =IFERROR(TRIM(INDEX('Raw Data'!$J$5:$J$400,MATCH($B10,'Raw Data'!$H$5:$H$400,0))),"") -> Dollar General #20582 | D10: =IFERROR(INDEX('Store List'!$B$4:$B$300,MATCH($C10,'Store List'!$A$4:$A$300,0)),"") -> 46098 | E10: Enclosure Seal | G10: =IF($E10="","",IFERROR(IF(OR(NOT(ISNUMBER($D10)),NOT(ISNUMBER(INDEX(Settings!$E$4:$E$80,MATCH($E10,Settings!$A$4:$A$80,0))))),"No",IF($D10>INDEX(Settings!$E$4:$E$80,MATCH($E10,Settings!$A$4:$A$80,0)),"Yes","No")),"")) -> No | H10: =IFERROR(TRIM(INDEX('Raw Data'!$S$5:$S$400,MATCH($B10,'Raw Data'!$H$5:$H$400,0))),"") -> RLN3MA/MY26B014956, LEFT ~ RLN2MA/ MY26B016476, LEFT
A11: =IFERROR(INDEX('Raw Data'!$D$5:$D$400,MATCH($B11,'Raw Data'!$H$5:$H$400,0)),"") -> 46100.539 | B11: WO-0536090 | C11: =IFERROR(TRIM(INDEX('Raw Data'!$J$5:$J$400,MATCH($B11,'Raw Data'!$H$5:$H$400,0))),"") -> Dollar General #04117 | D11: =IFERROR(INDEX('Store List'!$B$4:$B$300,MATCH($C11,'Store List'!$A$4:$A$300,0)),"") -> 46098 | E11: Communication problem | F11: Microblock | G11: =IF($E11="","",IFERROR(IF(OR(NOT(ISNUMBER($D11)),NOT(ISNUMBER(INDEX(Settings!$E$4:$E$80,MATCH($E11,Settings!$A$4:$A$80,0))))),"No",IF($D11>INDEX(Settings!$E$4:$E$80,MATCH($E11,Settings!$A$4:$A$80,0)),"Yes","No")),"")) -> No | H11: =IFERROR(TRIM(INDEX('Raw Data'!$S$5:$S$400,MATCH($B11,'Raw Data'!$H$5:$H$400,0))),"")
A12: =IFERROR(INDEX('Raw Data'!$D$5:$D$400,MATCH($B12,'Raw Data'!$H$5:$H$400,0)),"") -> 46111.269 | B12: WO-0541495 | C12: =IFERROR(TRIM(INDEX('Raw Data'!$J$5:$J$400,MATCH($B12,'Raw Data'!$H$5:$H$400,0))),"") -> Dollar General #22149 | D12: =IFERROR(INDEX('Store List'!$B$4:$B$300,MATCH($C12,'Store List'!$A$4:$A$300,0)),"") -> 46092 | E12: Component Failure | G12: =IF($E12="","",IFERROR(IF(OR(NOT(ISNUMBER($D12)),NOT(ISNUMBER(INDEX(Settings!$E$4:$E$80,MATCH($E12,Settings!$A$4:$A$80,0))))),"No",IF($D12>INDEX(Settings!$E$4:$E$80,MATCH($E12,Settings!$A$4:$A$80,0)),"Yes","No")),"")) -> No | H12: =IFERROR(TRIM(INDEX('Raw Data'!$S$5:$S$400,MATCH($B12,'Raw Data'!$H$5:$H$400,0))),"") -> RMN5MA/MY26B013852 RLN3MA/MY26B013833 ~ RLN2MA/MY26B013807 ~ RFMN4/MY21G066701
A13: =IFERROR(INDEX('Raw Data'!$D$5:$D$400,MATCH($B13,'Raw Data'!$H$5:$H$400,0)),"") -> 46111.266 | B13: WO-0541490 | C13: =IFERROR(TRIM(INDEX('Raw Data'!$J$5:$J$400,MATCH($B13,'Raw Data'!$H$5:$H$400,0))),"") -> Dollar General #6099 | D13: =IFERROR(INDEX('Store List'!$B$4:$B$300,MATCH($C13,'Store List'!$A$4:$A$300,0)),"") -> 46098 | E13: Communication problem | F13: Microblock | G13: =IF($E13="","",IFERROR(IF(OR(NOT(ISNUMBER($D13)),NOT(ISNUMBER(INDEX(Settings!$E$4:$E$80,MATCH($E13,Settings!$A$4:$A$80,0))))),"No",IF($D13>INDEX(Settings!$E$4:$E$80,MATCH($E13,Settings!$A$4:$A$80,0)),"Yes","No")),"")) -> No | H13: =IFERROR(TRIM(INDEX('Raw Data'!$S$5:$S$400,MATCH($B13,'Raw Data'!$H$5:$H$400,0))),"") -> N/A
A14: =IFERROR(INDEX('Raw Data'!$D$5:$D$400,MATCH($B14,'Raw Data'!$H$5:$H$400,0)),"") -> 46111.32 | B14: WO-0541572 | C14: =IFERROR(TRIM(INDEX('Raw Data'!$J$5:$J$400,MATCH($B14,'Raw Data'!$H$5:$H$400,0))),"") -> Dollar General 22799 | D14: =IFERROR(INDEX('Store List'!$B$4:$B$300,MATCH($C14,'Store List'!$A$4:$A$300,0)),"") -> 46099 | E14: Wrong program | G14: =IF($E14="","",IFERROR(IF(OR(NOT(ISNUMBER($D14)),NOT(ISNUMBER(INDEX(Settings!$E$4:$E$80,MATCH($E14,Settings!$A$4:$A$80,0))))),"No",IF($D14>INDEX(Settings!$E$4:$E$80,MATCH($E14,Settings!$A$4:$A$80,0)),"Yes","No")),"")) -> No | H14: =IFERROR(TRIM(INDEX('Raw Data'!$S$5:$S$400,MATCH($B14,'Raw Data'!$H$5:$H$400,0))),"") -> RLN2MA/MY26B014943
A15: =IFERROR(INDEX('Raw Data'!$D$5:$D$400,MATCH($B15,'Raw Data'!$H$5:$H$400,0)),"") -> 46111.378 | B15: WO-0541656 | C15: =IFERROR(TRIM(INDEX('Raw Data'!$J$5:$J$400,MATCH($B15,'Raw Data'!$H$5:$H$400,0))),"") -> DOLLAR GENERAL #10369 | D15: =IFERROR(INDEX('Store List'!$B$4:$B$300,MATCH($C15,'Store List'!$A$4:$A$300,0)),"") -> 46106 | E15: Wrong / Loose wiring | G15: =IF($E15="","",IFERROR(IF(OR(NOT(ISNUMBER($D15)),NOT(ISNUMBER(INDEX(Settings!$E$4:$E$80,MATCH($E15,Settings!$A$4:$A$80,0))))),"No",IF($D15>INDEX(Settings!$E$4:$E$80,MATCH($E15,Settings!$A$4:$A$80,0)),"Yes","No")),"")) -> No | H15: =IFERROR(TRIM(INDEX('Raw Data'!$S$5:$S$400,MATCH($B15,'Raw Data'!$H$5:$H$400,0))),"") -> RMN5MA/MY26B016046, LEFT
A16: =IFERROR(INDEX('Raw Data'!$D$5:$D$400,MATCH($B16,'Raw Data'!$H$5:$H$400,0)),"") -> 46114.614 | B16: WO-0545426 | C16: =IFERROR(TRIM(INDEX('Raw Data'!$J$5:$J$400,MATCH($B16,'Raw Data'!$H$5:$H$400,0))),"") -> Dollar General #12879 | D16: =IFERROR(INDEX('Store List'!$B$4:$B$300,MATCH($C16,'Store List'!$A$4:$A$300,0)),"") -> 46106 | E16: Wrong / Loose wiring | G16: =IF($E16="","",IFERROR(IF(OR(NOT(ISNUMBER($D16)),NOT(ISNUMBER(INDEX(Settings!$E$4:$E$80,MATCH($E16,Settings!$A$4:$A$80,0))))),"No",IF($D16>INDEX(Settings!$E$4:$E$80,MATCH($E16,Settings!$A$4:$A$80,0)),"Yes","No")),"")) -> No | H16: =IFERROR(TRIM(INDEX('Raw Data'!$S$5:$S$400,MATCH($B16,'Raw Data'!$H$5:$H$400,0))),"") -> RMN5MA/MY26B016549, LEFT
A17: =IFERROR(INDEX('Raw Data'!$D$5:$D$400,MATCH($B17,'Raw Data'!$H$5:$H$400,0)),"") -> 46114.637 | B17: WO-0545463 | C17: =IFERROR(TRIM(INDEX('Raw Data'!$J$5:$J$400,MATCH($B17,'Raw Data'!$H$5:$H$400,0))),"") -> DOLLAR GENERAL #10369 | D17: =IFERROR(INDEX('Store List'!$B$4:$B$300,MATCH($C17,'Store List'!$A$4:$A$300,0)),"") -> 46106 | E17: Wrong / Loose wiring | G17: =IF($E17="","",IFERROR(IF(OR(NOT(ISNUMBER($D17)),NOT(ISNUMBER(INDEX(Settings!$E$4:$E$80,MATCH($E17,Settings!$A$4:$A$80,0))))),"No",IF($D17>INDEX(Settings!$E$4:$E$80,MATCH($E17,Settings!$A$4:$A$80,0)),"Yes","No")),"")) -> No | H17: =IFERROR(TRIM(INDEX('Raw Data'!$S$5:$S$400,MATCH($B17,'Raw Data'!$H$5:$H$400,0))),"") -> RMN4MA/MY26B016036, LEFT
A18: =IFERROR(INDEX('Raw Data'!$D$5:$D$400,MATCH($B18,'Raw Data'!$H$5:$H$400,0)),"") -> 46116.77 | B18: WO-0546538 | C18: =IFERROR(TRIM(INDEX('Raw Data'!$J$5:$J$400,MATCH($B18,'Raw Data'!$H$5:$H$400,0))),"") -> Dollar General #20876 | D18: =IFERROR(INDEX('Store List'!$B$4:$B$300,MATCH($C18,'Store List'!$A$4:$A$300,0)),"") -> 46112 | E18: High Store RH | G18: =IF($E18="","",IFERROR(IF(OR(NOT(ISNUMBER($D18)),NOT(ISNUMBER(INDEX(Settings!$E$4:$E$80,MATCH($E18,Settings!$A$4:$A$80,0))))),"No",IF($D18>INDEX(Settings!$E$4:$E$80,MATCH($E18,Settings!$A$4:$A$80,0)),"Yes","No")),"")) -> No | H18: =IFERROR(TRIM(INDEX('Raw Data'!$S$5:$S$400,MATCH($B18,'Raw Data'!$H$5:$H$400,0))),"") -> RLN2MA/MY26B013812
A19: =IFERROR(INDEX('Raw Data'!$D$5:$D$400,MATCH($B19,'Raw Data'!$H$5:$H$400,0)),"") -> 46118.548 | B19: WO-0547346 | C19: =IFERROR(TRIM(INDEX('Raw Data'!$J$5:$J$400,MATCH($B19,'Raw Data'!$H$5:$H$400,0))),"") -> Dollar General #6827 | D19: =IFERROR(INDEX('Store List'!$B$4:$B$300,MATCH($C19,'Store List'!$A$4:$A$300,0)),"") -> 46086 | E19: False Alarm | G19: =IF($E19="","",IFERROR(IF(OR(NOT(ISNUMBER($D19)),NOT(ISNUMBER(INDEX(Settings!$E$4:$E$80,MATCH($E19,Settings!$A$4:$A$80,0))))),"No",IF($D19>INDEX(Settings!$E$4:$E$80,MATCH($E19,Settings!$A$4:$A$80,0)),"Yes","No")),"")) -> No | H19: =IFERROR(TRIM(INDEX('Raw Data'!$S$5:$S$400,MATCH($B19,'Raw Data'!$H$5:$H$400,0))),"") -> RLN2MA/MY26b013811 ~ RLN3MA/MY26B013832
A20: =IFERROR(INDEX('Raw Data'!$D$5:$D$400,MATCH($B20,'Raw Data'!$H$5:$H$400,0)),"") -> 46120.392 | B20: WO-0548436 | C20: =IFERROR(TRIM(INDEX('Raw Data'!$J$5:$J$400,MATCH($B20,'Raw Data'!$H$5:$H$400,0))),"") -> Dollar General #3270 | D20: =IFERROR(INDEX('Store List'!$B$4:$B$300,MATCH($C20,'Store List'!$A$4:$A$300,0)),"") -> 46120 | E20: Component Failure | G20: =IF($E20="","",IFERROR(IF(OR(NOT(ISNUMBER($D20)),NOT(ISNUMBER(INDEX(Settings!$E$4:$E$80,MATCH($E20,Settings!$A$4:$A$80,0))))),"No",IF($D20>INDEX(Settings!$E$4:$E$80,MATCH($E20,Settings!$A$4:$A$80,0)),"Yes","No")),"")) -> No | H20: =IFERROR(TRIM(INDEX('Raw Data'!$S$5:$S$400,MATCH($B20,'Raw Data'!$H$5:$H$400,0))),"") -> MY26B016515
A21: =IFERROR(INDEX('Raw Data'!$D$5:$D$400,MATCH($B21,'Raw Data'!$H$5:$H$400,0)),"") -> 46119.611 | B21: WO-0548123 | C21: =IFERROR(TRIM(INDEX('Raw Data'!$J$5:$J$400,MATCH($B21,'Raw Data'!$H$5:$H$400,0))),"") -> Dollar General #14858 | D21: =IFERROR(INDEX('Store List'!$B$4:$B$300,MATCH($C21,'Store List'!$A$4:$A$300,0)),"") -> 46097 | E21: Door Torque | F21: Tech found door torque issue and adjusted it | G21: =IF($E21="","",IFERROR(IF(OR(NOT(ISNUMBER($D21)),NOT(ISNUMBER(INDEX(Settings!$E$4:$E$80,MATCH($E21,Settings!$A$4:$A$80,0))))),"No",IF($D21>INDEX(Settings!$E$4:$E$80,MATCH($E21,Settings!$A$4:$A$80,0)),"Yes","No")),"")) -> No | H21: =IFERROR(TRIM(INDEX('Raw Data'!$S$5:$S$400,MATCH($B21,'Raw Data'!$H$5:$H$400,0))),"") -> RMN5MA/MY26B016546, LEFT
A22: =IFERROR(INDEX('Raw Data'!$D$5:$D$400,MATCH($B22,'Raw Data'!$H$5:$H$400,0)),"") -> 46119.611 | B22: WO-0548123 | C22: =IFERROR(TRIM(INDEX('Raw Data'!$J$5:$J$400,MATCH($B22,'Raw Data'!$H$5:$H$400,0))),"") -> Dollar General #14858 | D22: =IFERROR(INDEX('Store List'!$B$4:$B$300,MATCH($C22,'Store List'!$A$4:$A$300,0)),"") -> 46097 | E22: Wrong / Loose wiring | G22: =IF($E22="","",IFERROR(IF(OR(NOT(ISNUMBER($D22)),NOT(ISNUMBER(INDEX(Settings!$E$4:$E$80,MATCH($E22,Settings!$A$4:$A$80,0))))),"No",IF($D22>INDEX(Settings!$E$4:$E$80,MATCH($E22,Settings!$A$4:$A$80,0)),"Yes","No")),"")) -> No | H22: =IFERROR(TRIM(INDEX('Raw Data'!$S$5:$S$400,MATCH($B22,'Raw Data'!$H$5:$H$400,0))),"") -> RMN5MA/MY26B016546, LEFT
A23: =IFERROR(INDEX('Raw Data'!$D$5:$D$400,MATCH($B23,'Raw Data'!$H$5:$H$400,0)),"") -> 46121.515 | B23: WO-0549298 | C23: =IFERROR(TRIM(INDEX('Raw Data'!$J$5:$J$400,MATCH($B23,'Raw Data'!$H$5:$H$400,0))),"") -> Dollar General #21016 | D23: =IFERROR(INDEX('Store List'!$B$4:$B$300,MATCH($C23,'Store List'!$A$4:$A$300,0)),"") -> 46119 | E23: Communication problem | G23: =IF($E23="","",IFERROR(IF(OR(NOT(ISNUMBER($D23)),NOT(ISNUMBER(INDEX(Settings!$E$4:$E$80,MATCH($E23,Settings!$A$4:$A$80,0))))),"No",IF($D23>INDEX(Settings!$E$4:$E$80,MATCH($E23,Settings!$A$4:$A$80,0)),"Yes","No")),"")) -> No | H23: =IFERROR(TRIM(INDEX('Raw Data'!$S$5:$S$400,MATCH($B23,'Raw Data'!$H$5:$H$400,0))),"") -> RLN2MA/MY26B015995
A24: =IFERROR(INDEX('Raw Data'!$D$5:$D$400,MATCH($B24,'Raw Data'!$H$5:$H$400,0)),"") -> 46122.574 | B24: WO-0549951 | C24: =IFERROR(TRIM(INDEX('Raw Data'!$J$5:$J$400,MATCH($B24,'Raw Data'!$H$5:$H$400,0))),"") -> Dollar General #21223 | D24: =IFERROR(INDEX('Store List'!$B$4:$B$300,MATCH($C24,'Store List'!$A$4:$A$300,0)),"") -> 46120 | E24: Ref. leak/ Low charge | F24: Microblock | G24: =IF($E24="","",IFERROR(IF(OR(NOT(ISNUMBER($D24)),NOT(ISNUMBER(INDEX(Settings!$E$4:$E$80,MATCH($E24,Settings!$A$4:$A$80,0))))),"No",IF($D24>INDEX(Settings!$E$4:$E$80,MATCH($E24,Settings!$A$4:$A$80,0)),"Yes","No")),"")) -> No | H24: =IFERROR(TRIM(INDEX('Raw Data'!$S$5:$S$400,MATCH($B24,'Raw Data'!$H$5:$H$400,0))),"")
A25: =IFERROR(INDEX('Raw Data'!$D$5:$D$400,MATCH($B25,'Raw Data'!$H$5:$H$400,0)),"") -> 46120.636 | B25: WO-0548822 | C25: =IFERROR(TRIM(INDEX('Raw Data'!$J$5:$J$400,MATCH($B25,'Raw Data'!$H$5:$H$400,0))),"") -> Dollar General #13338 | D25: =IFERROR(INDEX('Store List'!$B$4:$B$300,MATCH($C25,'Store List'!$A$4:$A$300,0)),"") -> 46092 | E25: Component Failure | G25: =IF($E25="","",IFERROR(IF(OR(NOT(ISNUMBER($D25)),NOT(ISNUMBER(INDEX(Settings!$E$4:$E$80,MATCH($E25,Settings!$A$4:$A$80,0))))),"No",IF($D25>INDEX(Settings!$E$4:$E$80,MATCH($E25,Settings!$A$4:$A$80,0)),"Yes","No")),"")) -> No | H25: =IFERROR(TRIM(INDEX('Raw Data'!$S$5:$S$400,MATCH($B25,'Raw Data'!$H$5:$H$400,0))),"") -> RLN2MA/MY26B013807, RLN3MA/MY26B013833, RMN5MA/MY26B013852
A26: =IFERROR(INDEX('Raw Data'!$D$5:$D$400,MATCH($B26,'Raw Data'!$H$5:$H$400,0)),"") -> 46121.501 | B26: WO-0549280 | C26: =IFERROR(TRIM(INDEX('Raw Data'!$J$5:$J$400,MATCH($B26,'Raw Data'!$H$5:$H$400,0))),"") -> Dollar General #20407 | D26: =IFERROR(INDEX('Store List'!$B$4:$B$300,MATCH($C26,'Store List'!$A$4:$A$300,0)),"") -> 46119 | E26: Ref. leak/ Low charge | G26: =IF($E26="","",IFERROR(IF(OR(NOT(ISNUMBER($D26)),NOT(ISNUMBER(INDEX(Settings!$E$4:$E$80,MATCH($E26,Settings!$A$4:$A$80,0))))),"No",IF($D26>INDEX(Settings!$E$4:$E$80,MATCH($E26,Settings!$A$4:$A$80,0)),"Yes","No")),"")) -> No | H26: =IFERROR(TRIM(INDEX('Raw Data'!$S$5:$S$400,MATCH($B26,'Raw Data'!$H$5:$H$400,0))),"") -> RLN3MA/MY26B016017, RIGHT
A27: =IFERROR(INDEX('Raw Data'!$D$5:$D$400,MATCH($B27,'Raw Data'!$H$5:$H$400,0)),"") -> 46121.501 | B27: WO-0549280 | C27: =IFERROR(TRIM(INDEX('Raw Data'!$J$5:$J$400,MATCH($B27,'Raw Data'!$H$5:$H$400,0))),"") -> Dollar General #20407 | D27: =IFERROR(INDEX('Store List'!$B$4:$B$300,MATCH($C27,'Store List'!$A$4:$A$300,0)),"") -> 46119 | E27: Defrost Sync | G27: =IF($E27="","",IFERROR(IF(OR(NOT(ISNUMBER($D27)),NOT(ISNUMBER(INDEX(Settings!$E$4:$E$80,MATCH($E27,Settings!$A$4:$A$80,0))))),"No",IF($D27>INDEX(Settings!$E$4:$E$80,MATCH($E27,Settings!$A$4:$A$80,0)),"Yes","No")),"")) -> No | H27: =IFERROR(TRIM(INDEX('Raw Data'!$S$5:$S$400,MATCH($B27,'Raw Data'!$H$5:$H$400,0))),"") -> RLN3MA/MY26B016017, RIGHT
A28: =IFERROR(INDEX('Raw Data'!$D$5:$D$400,MATCH($B28,'Raw Data'!$H$5:$H$400,0)),"") -> 46125.433 | B28: WO-0551078 | C28: =IFERROR(TRIM(INDEX('Raw Data'!$J$5:$J$400,MATCH($B28,'Raw Data'!$H$5:$H$400,0))),"") -> Dollar General #14858 | D28: =IFERROR(INDEX('Store List'!$B$4:$B$300,MATCH($C28,'Store List'!$A$4:$A$300,0)),"") -> 46097 | E28: Return Air blocked | G28: =IF($E28="","",IFERROR(IF(OR(NOT(ISNUMBER($D28)),NOT(ISNUMBER(INDEX(Settings!$E$4:$E$80,MATCH($E28,Settings!$A$4:$A$80,0))))),"No",IF($D28>INDEX(Settings!$E$4:$E$80,MATCH($E28,Settings!$A$4:$A$80,0)),"Yes","No")),"")) -> No | H28: =IFERROR(TRIM(INDEX('Raw Data'!$S$5:$S$400,MATCH($B28,'Raw Data'!$H$5:$H$400,0))),"") -> RLN2MA/MY26B016475, LEFT
A29: =IFERROR(INDEX('Raw Data'!$D$5:$D$400,MATCH($B29,'Raw Data'!$H$5:$H$400,0)),"") -> 46126.384 | B29: WO-0551833 | C29: =IFERROR(TRIM(INDEX('Raw Data'!$J$5:$J$400,MATCH($B29,'Raw Data'!$H$5:$H$400,0))),"") -> Dollar General #21016 | D29: =IFERROR(INDEX('Store List'!$B$4:$B$300,MATCH($C29,'Store List'!$A$4:$A$300,0)),"") -> 46119 | E29: Unknown | G29: =IF($E29="","",IFERROR(IF(OR(NOT(ISNUMBER($D29)),NOT(ISNUMBER(INDEX(Settings!$E$4:$E$80,MATCH($E29,Settings!$A$4:$A$80,0))))),"No",IF($D29>INDEX(Settings!$E$4:$E$80,MATCH($E29,Settings!$A$4:$A$80,0)),"Yes","No")),"")) -> No | H29: =IFERROR(TRIM(INDEX('Raw Data'!$S$5:$S$400,MATCH($B29,'Raw Data'!$H$5:$H$400,0))),"") -> RMN3MA/MY26B016499
A30: =IFERROR(INDEX('Raw Data'!$D$5:$D$400,MATCH($B30,'Raw Data'!$H$5:$H$400,0)),"") -> 46126.512 | B30: WO-0552039 | C30: =IFERROR(TRIM(INDEX('Raw Data'!$J$5:$J$400,MATCH($B30,'Raw Data'!$H$5:$H$400,0))),"") -> Dollar General #14104 | D30: =IFERROR(INDEX('Store List'!$B$4:$B$300,MATCH($C30,'Store List'!$A$4:$A$300,0)),"") -> 46105 | E30: Freedom | G30: =IF($E30="","",IFERROR(IF(OR(NOT(ISNUMBER($D30)),NOT(ISNUMBER(INDEX(Settings!$E$4:$E$80,MATCH($E30,Settings!$A$4:$A$80,0))))),"No",IF($D30>INDEX(Settings!$E$4:$E$80,MATCH($E30,Settings!$A$4:$A$80,0)),"Yes","No")),"")) -> No | H30: =IFERROR(TRIM(INDEX('Raw Data'!$S$5:$S$400,MATCH($B30,'Raw Data'!$H$5:$H$400,0))),"") -> RLN2MA/MY26B015990 Left
A31: =IFERROR(INDEX('Raw Data'!$D$5:$D$400,MATCH($B31,'Raw Data'!$H$5:$H$400,0)),"") -> 46126.52 | B31: WO-0552056 | C31: =IFERROR(TRIM(INDEX('Raw Data'!$J$5:$J$400,MATCH($B31,'Raw Data'!$H$5:$H$400,0))),"") -> Dollar General #22286 | D31: =IFERROR(INDEX('Store List'!$B$4:$B$300,MATCH($C31,'Store List'!$A$4:$A$300,0)),"") -> 46099 | E31: False Alarm | G31: =IF($E31="","",IFERROR(IF(OR(NOT(ISNUMBER($D31)),NOT(ISNUMBER(INDEX(Settings!$E$4:$E$80,MATCH($E31,Settings!$A$4:$A$80,0))))),"No",IF($D31>INDEX(Settings!$E$4:$E$80,MATCH($E31,Settings!$A$4:$A$80,0)),"Yes","No")),"")) -> No | H31: =IFERROR(TRIM(INDEX('Raw Data'!$S$5:$S$400,MATCH($B31,'Raw Data'!$H$5:$H$400,0))),"") -> RLN2MA/MY26B014938, LEFT
A32: =IFERROR(INDEX('Raw Data'!$D$5:$D$400,MATCH($B32,'Raw Data'!$H$5:$H$400,0)),"") -> 46126.525 | B32: WO-0552063 | C32: =IFERROR(TRIM(INDEX('Raw Data'!$J$5:$J$400,MATCH($B32,'Raw Data'!$H$5:$H$400,0))),"") -> Dollar General #20876 | D32: =IFERROR(INDEX('Store List'!$B$4:$B$300,MATCH($C32,'Store List'!$A$4:$A$300,0)),"") -> 46112 | E32: High Store RH | G32: =IF($E32="","",IFERROR(IF(OR(NOT(ISNUMBER($D32)),NOT(ISNUMBER(INDEX(Settings!$E$4:$E$80,MATCH($E32,Settings!$A$4:$A$80,0))))),"No",IF($D32>INDEX(Settings!$E$4:$E$80,MATCH($E32,Settings!$A$4:$A$80,0)),"Yes","No")),"")) -> No | H32: =IFERROR(TRIM(INDEX('Raw Data'!$S$5:$S$400,MATCH($B32,'Raw Data'!$H$5:$H$400,0))),"") -> RLN2MA/MY26B013812
A33: =IFERROR(INDEX('Raw Data'!$D$5:$D$400,MATCH($B33,'Raw Data'!$H$5:$H$400,0)),"") -> 46126.535 | B33: WO-0552080 | C33: =IFERROR(TRIM(INDEX('Raw Data'!$J$5:$J$400,MATCH($B33,'Raw Data'!$H$5:$H$400,0))),"") -> Dollar General #22281 | D33: =IFERROR(INDEX('Store List'!$B$4:$B$300,MATCH($C33,'Store List'!$A$4:$A$300,0)),"") -> 46118 | E33: Defrost Sync | G33: =IF($E33="","",IFERROR(IF(OR(NOT(ISNUMBER($D33)),NOT(ISNUMBER(INDEX(Settings!$E$4:$E$80,MATCH($E33,Settings!$A$4:$A$80,0))))),"No",IF($D33>INDEX(Settings!$E$4:$E$80,MATCH($E33,Settings!$A$4:$A$80,0)),"Yes","No")),"")) -> No | H33: =IFERROR(TRIM(INDEX('Raw Data'!$S$5:$S$400,MATCH($B33,'Raw Data'!$H$5:$H$400,0))),"") -> RLN3MA/MY26B016019, RIGHT
A34: =IFERROR(INDEX('Raw Data'!$D$5:$D$400,MATCH($B34,'Raw Data'!$H$5:$H$400,0)),"") -> 46126.535 | B34: WO-0552080 | C34: =IFERROR(TRIM(INDEX('Raw Data'!$J$5:$J$400,MATCH($B34,'Raw Data'!$H$5:$H$400,0))),"") -> Dollar General #22281 | D34: =IFERROR(INDEX('Store List'!$B$4:$B$300,MATCH($C34,'Store List'!$A$4:$A$300,0)),"") -> 46118 | E34: False Alarm | G34: =IF($E34="","",IFERROR(IF(OR(NOT(ISNUMBER($D34)),NOT(ISNUMBER(INDEX(Settings!$E$4:$E$80,MATCH($E34,Settings!$A$4:$A$80,0))))),"No",IF($D34>INDEX(Settings!$E$4:$E$80,MATCH($E34,Settings!$A$4:$A$80,0)),"Yes","No")),"")) -> No | H34: =IFERROR(TRIM(INDEX('Raw Data'!$S$5:$S$400,MATCH($B34,'Raw Data'!$H$5:$H$400,0))),"") -> RLN3MA/MY26B016019, RIGHT
A35: =IFERROR(INDEX('Raw Data'!$D$5:$D$400,MATCH($B35,'Raw Data'!$H$5:$H$400,0)),"") -> 46126.541 | B35: WO-0552093 | C35: =IFERROR(TRIM(INDEX('Raw Data'!$J$5:$J$400,MATCH($B35,'Raw Data'!$H$5:$H$400,0))),"") -> Dollar General #3270 | D35: =IFERROR(INDEX('Store List'!$B$4:$B$300,MATCH($C35,'Store List'!$A$4:$A$300,0)),"") -> 46120 | E35: Ref. leak/ Low charge | G35: =IF($E35="","",IFERROR(IF(OR(NOT(ISNUMBER($D35)),NOT(ISNUMBER(INDEX(Settings!$E$4:$E$80,MATCH($E35,Settings!$A$4:$A$80,0))))),"No",IF($D35>INDEX(Settings!$E$4:$E$80,MATCH($E35,Settings!$A$4:$A$80,0)),"Yes","No")),"")) -> No | H35: =IFERROR(TRIM(INDEX('Raw Data'!$S$5:$S$400,MATCH($B35,'Raw Data'!$H$5:$H$400,0))),"") -> RLN3MA/MY26B016488, RIGHT
A36: =IFERROR(INDEX('Raw Data'!$D$5:$D$400,MATCH($B36,'Raw Data'!$H$5:$H$400,0)),"") -> 46126.559 | B36: WO-0552123 | C36: =IFERROR(TRIM(INDEX('Raw Data'!$J$5:$J$400,MATCH($B36,'Raw Data'!$H$5:$H$400,0))),"") -> Dollar General #22613 | D36: =IFERROR(INDEX('Store List'!$B$4:$B$300,MATCH($C36,'Store List'!$A$4:$A$300,0)),"") -> 46099 | E36: Wrong / Loose wiring | G36: =IF($E36="","",IFERROR(IF(OR(NOT(ISNUMBER($D36)),NOT(ISNUMBER(INDEX(Settings!$E$4:$E$80,MATCH($E36,Settings!$A$4:$A$80,0))))),"No",IF($D36>INDEX(Settings!$E$4:$E$80,MATCH($E36,Settings!$A$4:$A$80,0)),"Yes","No")),"")) -> No | H36: =IFERROR(TRIM(INDEX('Raw Data'!$S$5:$S$400,MATCH($B36,'Raw Data'!$H$5:$H$400,0))),"") -> RLN2MA/MY26B014941
... A40: =IFERROR(INDEX('Raw Data'!$D$5:$D$400,MATCH($B40,'Raw Data'!$H$5:$H$400,0)),"") -> 46127.322 | B40: WO-0552572 | C40: =IFERROR(TRIM(INDEX('Raw Data'!$J$5:$J$400,MATCH($B40,'Raw Data'!$H$5:$H$400,0))),"") -> Dollar General #21377 | D40: =IFERROR(INDEX('Store List'!$B$4:$B$300,MATCH($C40,'Store List'!$A$4:$A$300,0)),"") -> 46093 | E40: Door - general | G40: =IF($E40="","",IFERROR(IF(OR(NOT(ISNUMBER($D40)),NOT(ISNUMBER(INDEX(Settings!$E$4:$E$80,MATCH($E40,Settings!$A$4:$A$80,0))))),"No",IF($D40>INDEX(Settings!$E$4:$E$80,MATCH($E40,Settings!$A$4:$A$80,0)),"Yes","No")),"")) -> No | H40: =IFERROR(TRIM(INDEX('Raw Data'!$S$5:$S$400,MATCH($B40,'Raw Data'!$H$5:$H$400,0))),"") -> RLN2MA/MY26B013804, LEFT
A41: =IFERROR(INDEX('Raw Data'!$D$5:$D$400,MATCH($B41,'Raw Data'!$H$5:$H$400,0)),"") -> 46128.455 | B41: WO-0553537 | C41: =IFERROR(TRIM(INDEX('Raw Data'!$J$5:$J$400,MATCH($B41,'Raw Data'!$H$5:$H$400,0))),"") -> Dollar General #21135 | D41: =IFERROR(INDEX('Store List'!$B$4:$B$300,MATCH($C41,'Store List'!$A$4:$A$300,0)),"") -> 46106 | E41: Door Torque | F41: No comments from tech. but looking at the data, this is a door not closing issue which is most likely because of door torque | G41: =IF($E41="","",IFERROR(IF(OR(NOT(ISNUMBER($D41)),NOT(ISNUMBER(INDEX(Settings!$E$4:$E$80,MATCH($E41,Settings!$A$4:$A$80,0))))),"No",IF($D41>INDEX(Settings!$E$4:$E$80,MATCH($E41,Settings!$A$4:$A$80,0)),"Yes","No")),"")) -> No | H41: =IFERROR(TRIM(INDEX('Raw Data'!$S$5:$S$400,MATCH($B41,'Raw Data'!$H$5:$H$400,0))),"") -> RMN3MA/MY26b016480
A42: =IFERROR(INDEX('Raw Data'!$D$5:$D$400,MATCH($B42,'Raw Data'!$H$5:$H$400,0)),"") -> 46128.455 | B42: WO-0553537 | C42: =IFERROR(TRIM(INDEX('Raw Data'!$J$5:$J$400,MATCH($B42,'Raw Data'!$H$5:$H$400,0))),"") -> Dollar General #21135 | D42: =IFERROR(INDEX('Store List'!$B$4:$B$300,MATCH($C42,'Store List'!$A$4:$A$300,0)),"") -> 46106 | E42: Drain tube blocked | G42: =IF($E42="","",IFERROR(IF(OR(NOT(ISNUMBER($D42)),NOT(ISNUMBER(INDEX(Settings!$E$4:$E$80,MATCH($E42,Settings!$A$4:$A$80,0))))),"No",IF($D42>INDEX(Settings!$E$4:$E$80,MATCH($E42,Settings!$A$4:$A$80,0)),"Yes","No")),"")) -> No | H42: =IFERROR(TRIM(INDEX('Raw Data'!$S$5:$S$400,MATCH($B42,'Raw Data'!$H$5:$H$400,0))),"") -> RMN3MA/MY26b016480
A43: =IFERROR(INDEX('Raw Data'!$D$5:$D$400,MATCH($B43,'Raw Data'!$H$5:$H$400,0)),"") -> 46130.378 | B43: WO-0554820 | C43: =IFERROR(TRIM(INDEX('Raw Data'!$J$5:$J$400,MATCH($B43,'Raw Data'!$H$5:$H$400,0))),"") -> Dollar General #22982 | D43: =IFERROR(INDEX('Store List'!$B$4:$B$300,MATCH($C43,'Store List'!$A$4:$A$300,0)),"") -> 46126 | E43: Door - general | G43: =IF($E43="","",IFERROR(IF(OR(NOT(ISNUMBER($D43)),NOT(ISNUMBER(INDEX(Settings!$E$4:$E$80,MATCH($E43,Settings!$A$4:$A$80,0))))),"No",IF($D43>INDEX(Settings!$E$4:$E$80,MATCH($E43,Settings!$A$4:$A$80,0)),"Yes","No")),"")) -> No | H43: =IFERROR(TRIM(INDEX('Raw Data'!$S$5:$S$400,MATCH($B43,'Raw Data'!$H$5:$H$400,0))),"") -> RLN4MA/MY26B014967, LEFT
...

Sheet Raw Data
A1: Raw Data - paste new CRM export rows at the bottom | B1: Raw Data - paste new CRM export rows at the bottom | C1: Raw Data - paste new CRM export rows at the bottom | D1: Raw Data - paste new CRM export rows at the bottom
A3: Possible duplicate work orders: | C3: =SUMPRODUCT(('Raw Data'!$H$5:$H$400<>"")*(COUNTIF('Raw Data'!$H$5:$H$400,'Raw Data'!$H$5:$H$400)>1)) -> 4
A4: (Do Not Modify) WO Number | B4: (Do Not Modify) Row Checksum | C4: (Do Not Modify) Modified On | D4: DATE | E4: APRILS NOTES | F4: STATUS | G4: COMPLETED DATE | H4: BOS WORK ORDER | I4: BRANCH | J4: STORE | K4: CITY | L4: STATE | M4: PO | N4: CALLER | O4: PROBLEM CATEGORY | P4: REPLACEMENT PARTS | Q4: NON-WARRANTY BILLABLE | R4: FR SUBMITTED YES/NO | S4: CASE MODEL/SERIAL NUMBER | T4: PICTURES BOS | U4: Job Scope | V4: WORK SUMMARY
D5: 46209.674 | F5: Canceled | G5: 46209 | H5: WO-0608904 | I5: San Antonio, TX | J5: Dollar General #20761 | K5: Pettus | L5: TX | M5: TAVANT/PRODUCT CARE | N5: STORE CONNECT | O5: TEMPERATURE | S5: RLN2MA / MY26B013813 | U5: High Temperature Alarm | V5: Product Care Team cancelled the call
D6: 46209.641 | F6: Completed | G6: 46210 | H6: WO-0608855 | I6: Dallas, TX | J6: Dollar General #3277 | K6: Garland | L6: TX | M6: 5169188 | N6: FEXA | O6: TEMPERATURE | S6: RLN3MA / MY26D028108 | U6: Invalid Temperature Reading | V6: I found case at temp -8 down to - 10 i found left hand door not closing all the way and probably causing issues store had roped off the case i repaired torque rod and adjusted it . No other issues found with the case. Store ac is not working properly could case issues not sure.
D7: 46209.492 | E7: ETA 7/6 | F7: Scheduled | H7: WO-0608593 | I7: Kansas City, MO (Lenexa) | J7: Dollar General #1768 | K7: Nixa | L7: MO | M7: 5163557 | N7: FEXA | O7: WATER LEAKING | S7: RLN2MA / MY26D028097 | U7: Water leaking from under the unit and excessive condinsation on the doors - multiple units effected
D8: 46209.353 | F8: Canceled | H8: WO-0608327 | I8: Tulsa, OK | J8: Dollar General #21606 | K8: Porum | L8: OK | M8: TAVANT/PRODUCT CARE | N8: STORE CONNECT | O8: TEMPERATURE | S8: RLN3MA / MY26B013826 | U8: High Temperature Alarm | V8: Kindly recall the dispatch for below case, as case trends and working seems to be normal, kindly acknowledge here once it is recalled.
D9: 46206.953 | F9: Completed | G9: 46210 | H9: WO-0607313 | I9: Southern | J9: Dollar General #21375 | K9: Oxford | L9: AR | M9: 5162624 | N9: FEXA | O9: ICE BUILD UP | S9: RLN3MA / MY26B01382 | U9: There is a block of ice on the inside and top of the unit | V9: Email from Young, Bradley <Bradley.Young@hussmann.onmicrosoft.com>
D10: 46206.943 | E10: ETA 7/8 | F10: Scheduled | H10: WO-0607311 | I10: Dallas, TX | J10: Dollar General #22930 | K10: Forestburg | L10: TX | M10: 5162381 | N10: FEXA | O10: WATER LEAKING INTO UNIT | S10: RLN4MA / MY26B014974 | U10: There is water running into the unit and down the shelves and freezing
D11: 46206.611 | F11: Completed | H11: WO-0607008 | I11: Southern | J11: Dollar General #21838 | K11: Belle Chasse | L11: LA | M11: TAVANT/PRODUCT CARE | N11: STORE CONNECT | O11: TEMPERATURE | S11: RLN3MA / MY26E039365 | U11: High Temperature Alarm | V11: Found ice dripping from top of cabinet. Checked to make sure the drain was clear. Removed top plate to inspect where water was coming from. Found spray foam and butyl had overflowed into airway and had ice forming on it and wicking water down to cabinet. Removed overflow and all ice. Observed for 45 minutes to ensure it didn't continue leaking. Observed defrost and proper drain function.
D12: 46206.036 | E12: Pinged Sarah for eta | F12: Send New Tech | H12: WO-0606554 | I12: Houston, TX | J12: Dollar General #14858 | K12: Houston | L12: TX | M12: TAVANT/PRODUCT CARE | N12: STORE CONNECT | O12: TEMPERATURE | S12: RLN2MA / MY26B016475 | U12: High Temperature Alarm
D13: 46206 | E13: Parts ordered and tech returning with propane | F13: Done - Send New Tech | H13: WO-0607304 | I13: Houston, TX | J13: Dollar General #22408 | K13: Angelton | L13: TX | M13: 5162382 | N13: FEXA | O13: TEMPERATURE | S13: RMN5MA/MY26E03940 | U13: Invalid Temperature Reading | V13: 7/7/2026 .Tech support called me after I left. 7/7/2026 One of the units might be under charged so they asked me to go back with some propaneChecked in with manager. Located 5 door case. Found unit at temp. Connected to both controllers. Found all sensors reading properly. Tried to get with tech support but couldnt get a hold of them. Found 1 torque rod and master that need to repaced. Got with andrew miller we checked all sensors . Will return when parts come in
D14: 46205.919 | F14: Canceled | G14: 46206 | H14: WO-0606498 | I14: Bolingbrook, IL | J14: Dollar General #8773 | K14: South Bend | L14: IN | M14: TAVANT/PRODUCT CARE | N14: STORE CONNECT | O14: TEMPERATURE | S14: RLN3MA / MY26B016492 | U14: High Temperature Alarm | V14: 7/3/2026 2:02AM Please recall the dispatch request, as the case has started returning to normal. Regards,Product Care Team
D15: 46205 | F15: Completed | G15: 46210 | H15: WO-0605720 | I15: Dallas, TX | J15: Dollar General #21664 | K15: Jacksonville | L15: TX | M15: TAVANT/PRODUCT CARE | N15: STORE CONNECT | O15: TEMPERATURE | S15: RMN5MA / MY26D033044 | U15: High Temperature Alarm | V15: 07/02/26; Check new cases and found the new case, SN MY26D033044 warm in the left end. Case has two condensing units. Pull inside top cover to access the evap, evap clear. Condensing units are R290. Discharge temp feels low at the condenser inlet. Leak check unit, found no leaks. Will have to pick up an R290 charging kit and return. Spoke with the manager about it and they are fine. 07/06/26; Pick up R290 kit in Longview and return to the store. Install piercing valveson liquid and suction. Hookup hoses and vacuum pump, vacuum pump locked up. Pick up new vacuum pump. 07/07/26; Return to store. Activate piercing valves and pull vacuum. Leave unit on vacuum for an hour, vacuum stayed at 30". Weigh in 3.5 oz of R290. Discharge temp at condenser is at 110°F. Suction at 50# and discharge at 140#. Case temp droped to setpoint and cycled.
D16: 46205 | E16: ETA is 7/17 | F16: Return Needed | H16: WO-0606044 | I16: Denver, CO | J16: Dollar General #21938 | K16: Olathe | L16: CO | M16: TAVANT/Tim Smith (Installation) | N16: INTERNAL | O16: HUMIDITY SENSOR | V16: 07/02/26; Check new cases and found the new case, SN MY26D033044 warm in the left end. Case has two condensing units. Pull inside top cover to access the evap, evap clear. Condensing units are R290. Discharge temp feels low at the condenser inlet. Leak check unit, found no leaks. Will have to pick up an R290 charging kit and return. Spoke with the manager about it and they are fine. 07/06/26; Pick up R290 kit in Longview and return to the store. Install piercing valveson liquid and suction. Hookup hoses and vacuum pump, vacuum pump locked up. Pick up new vacuum pump. 07/07/26; Return to store. Activate piercing valves and pull vacuum. Leave unit on vacuum for an hour, vacuum stayed at 30". Weigh in 3.5 oz of R290. Discharge temp at condenser is at 110°F. Suction at 50# and discharge at 140#. Case temp droped to setpoint and cycled.
D17: 46205 | F17: Completed | G17: 46205 | H17: WO-0605513 | I17: Houston, TX | J17: Dollar General #22408 | K17: Angleton | L17: TX | M17: TAVANT/PRODUCT CARE | N17: STORE CONNECT | O17: TEMPERATURE | S17: RLN3MA / MY26F047534 | U17: High Temperature Alarm | V17: Checked in with manager. Located self contained unit. Found unit at -4 degrees. Right side condenser was not running. Connected to controller. Controller was calling for comp. Started going thru control wiring. Found a wiring issue. Repaired wiring. Started condenser up. Unit dropped to temp. Checked operation of unit. All okay work complete
D18: 46203 | F18: Completed | G18: 46205 | H18: WO-0603741 | I18: Bolingbrook, IL | J18: Dollar General #20597 | K18: Chicago | L18: IL | M18: TAVANT/PRODUCT CARE | N18: STORE CONNECT | O18: TEMPERATURE | S18: RLN3MA / MY26B016493 | U18: High Temperature Alarm | V18: 7/1/26 DE Arrived on site and checked in. On site for reach in freezer running warm. Case controllers were reading -8 and -4 upn arrival. Case went into defrost immediately after arrival. Let case run through its natural defrost cycle. After defrost, let case try to pull down to temp. Customers kept opening doors so case was struggling to pull down to temp. Doors were finally left closed long enough for case to pull down. Case temping at -.5 and .1 and still dropping upon departure. No issue found at this time. Cleaned up work area and checked out with manager Sylvia.
D19: 46203 | F19: Canceled | G19: 46204 | H19: WO-0603718 | I19: Southern | J19: Dollar General #13069 | K19: Laurel | L19: MS | M19: TAVANT/PRODUCT CARE | N19: STORE CONNECT | O19: TEMPERATURE | S19: RLN3MA / MY26B016491 | U19: High Temperature Alarm | V19: 7/1 Kindly recall the dispatch for below case, as case trends and working seems to be normal, kindly acknowledge here once it is recalled. From Product Care 6/30 Roll call for AM as store closes in 35 minutes
D20: 46203 | F20: Completed | G20: 46203 | H20: WO-0602689 | I20: Houston, TX | J20: Dollar General #20440 | K20: Sheridan | L20: TX | M20: TAVANT/PRODUCT CARE | N20: STORE CONNECT | O20: TEMPERATURE | S20: RLN3MA / MY26D032603 | U20: High Temperature Alarm | V20: 7/1 checked in with manager . Located rif self contained unit. Found unit at 18 degrees. Found ice build up on frame of case not allowing doors to close properly. Removed ice from frame , case started dropping to temp. Started looking into frame heater. Located anti sweat contoller in top left panel of case. Found good voltage coming in and out of contoller. Started tracing wiring for frame heater. Had to go wire for wire to locate frame heater. Found that frame heater wasnt wired properly. Fixed wiring. Frame heater started pulling correct amps , ice melted off frame. Checked operation of unit. Units are charged properly. Tried to check deforst but controllers were locked out. Had to get with tech support to download the correct app for carel controllers. Tested defrost. Had to install a self tapper on condenser because ribbits had come loose . All okay. Work complete
D21: 46202 | E21: Pinged Heidi - ETA was 7/6 | F21: Unscheduled | H21: WO-0601570 | I21: Tulsa, OK | J21: Dollar General #22149 | K21: Anton | L21: TX | M21: TAVANT/PRODUCT CARE | N21: STORE CONNECT | O21: TEMPERATURE | S21: RLN2MA / MY26B014945 | U21: High Temperature Alarm
D22: 46200.148 | F22: Completed | G22: 46200 | H22: WO-0600724 | I22: Southern | J22: Dollar General #20100 | K22: Paulina | L22: LA | M22: TAVANT/PRODUCT CARE | N22: STORE CONNECT | O22: TEMPERATURE | S22: RLN2MA MY26D029644 | U22: High Temperature Alarm | V22: Checked case and found that the evaporator coil was iced up and it was because there was a box of product that was keeping the door open, so after moving the box and closing the door i had to run the case in multiple defrost. After that case came back down yo temperature and its now running normally.
D23: 46199.431 | F23: Send New Tech | H23: WO-0599879 | I23: Houston, TX | J23: Dollar General #21359 | K23: Orange | L23: TX | M23: 5134984 | N23: FEXA | O23: TEMPERATURE | S23: RLN3MA / MY26B016014 | U23: Ice cream is melting and product damaged, water leaking under unit | V23: 6/26/26 Freezer iced up due to high humidity in area.customer removed all product then i deiced case.defrost heaters working properly.i also cleaned drain pan assembly.also cleaned condenser coils.then put unit it online.frerzer maintaining temperature -8 degrees
D24: 46199.417 | F24: Completed | G24: 46200 | H24: WO-0599854 | I24: Houston, TX | J24: Dollar General #20440 | K24: Sheridan | L24: TX | M24: 5140629 | N24: FEXA | O24: TEMPERATURE | S24: RLN3MA/ MY26D032603 | U24: Cooler keeps freezing up, causing door to form ice and it is not closing | V24: 6/26/26 Arrived on site checked in with manager. Found 3 door case with some ice building up at bottom of door. Removed ice pulled gaskets and set outside in the sun to warm up. Reinstalled and adjusted torque rods on Doors. Doors seem to be Sealing better and can not feel any air leaks. After talking to non-mechanical technician cases may not be leveled correctly. Checked with makeshift plumber Bob and cases seem to be leaning forward. Non-mechanical technicians or installing contractor may need to check level on cases. Cases are out of alarm at this time. Checked out with store m o d work order complete.
D25: 46199.177 | F25: Completed | G25: 46200 | H25: WO-0600225 | I25: Southern | J25: Dollar General #10520 | K25: Youngsville | L25: LA | M25: TAVANT/PRODUCT CARE | N25: STORE CONNECT | O25: TEMPERATURE | S25: RLN3MA / MY26E039362 | U25: High Temperature Alarm | V25: 6/27/26 Service call for frozen food micro blocks high temp. Drove to site, checked in, gained access to cases, all 3 micro blocks are working as they should with no alarm, and cases are at setpoint. Serial: MY26D029643 MODEL ID: RLN2MA MODEL ID: RLN3MA SERIAL: MY26E039362
D26: 46198.497 | F26: Completed | G26: 46199 | H26: WO-0599278 | I26: Southern | J26: Dollar General #13009 | K26: Wake Village | L26: TX | M26: TAVANT/PRODUCT CARE | N26: STORE CONNECT | O26: TEMPERATURE | S26: RLN2MA / MY26C019875 | U26: High Temperature Alarm | V26: 6/26/26 Arrived onsite to service Hussmann reach-in case. Recovered the existing R-290 refrigerant charge, pulled the system into a deep vacuum, and recharged the system with 3.5 oz of R-290. Restarted the unit and verified proper operation. Case temperature is currently -7°F and maintaining temperature as designed. Unit operating normally at this time. 6/25/26- inspected the system. Checked the airflow. Checked that the compressor was running. Determined that the system was low on R290. Will have Dave return tomorrow to gas up the system.
D27: 46198.312 | F27: Completed | G27: 46199 | H27: WO-0599624 | I27: Southern | J27: Dollar General #21838 | K27: Belle Chasse | L27: LA | M27: TAVANT/PRODUCT CARE | N27: STORE CONNECT | O27: TEMPERATURE | S27: RMN4MA/MY26E039403 | U27: High Temperature Alarm | V27: 6/26 Please recall the dispatch requst, as the case has started returning to normal. Regards, Product Care Team 6/25When i got to site i found the evaporator was iced up because the vendor had the doors open as he was installing sliders and fillling it with product, So i tested defrost out and its working normally the case will recover when they are done loading the case
D28: 46198.151 | F28: Completed | G28: 46198 | H28: WO-0599522 | I28: Bolingbrook, IL | J28: Dollar General #20597 | K28: Chicago | L28: IL | M28: TAVANT/PRODUCT CARE | N28: STORE CONNECT | O28: COIL ICING | S28: RLN3MA/MY26B016493 | U28: We are observing a coil icing | V28: 6/25/26 AN Model# RLN3MA Serial# MY26B016493 Drove to site. Arrived on site. Call for frozen 3 door icing up. Found right most door had gasket off at the bottom of the door keeping door open causing moisture to enter into case. Ice was forming on ceiling of case. Reinstalled gasket. Cleared ice forming on door frame. Door is now closing proper. Forced both controllers through multiple defrosts to clear any frost from coils. Cleared as much ice and moisture as possible. Monitored temps. Temps are dropping. At 0 degrees and still dropping. Cleaned up work area. Work complete
D29: 46197.197 | F29: Completed | G29: 46198 | H29: WO-0598739 | I29: RPM/Strategic Accounts | J29: Dollar General #6987 | K29: Pinetop | L29: AZ | M29: 5129550 | N29: FEXA | O29: TEMPERATURE | S29: RMN4MA/MY26E039399 | U29: I spoke with Marie (SM) and she said temperature seemed warm and product didn't look good and the temperature gauge was not working. | V29: Sub sending in tech notes
D30: 46196.488 | F30: Completed | G30: 46199 | H30: WO-0597607 | I30: RPM/Strategic Accounts | J30: Dollar General #21342 | K30: Klamath Falls | L30: OR | M30: 5130014 | N30: FEXA | O30: ICE BUILD UP | S30: RLN3MA/MY26B016018 | U30: Major Ice build up on the doors and leaking water on floor | V30: Sub confirms complete and will send in tech notes
D31: 46196.419 | F31: Completed | G31: 46196 | H31: WO-0597498 | I31: Phoenix, AZ | J31: Dollar General #22864 | K31: Tucson | L31: AZ | M31: 5119317 | N31: FEXA | O31: TEMPERATURE | S31: RMN5MA/MY26B016552 | U31: Not Keeping Temperature | V31: Arrived on site and checked in with mod. Cooler reach in at temp upon arrival. Pulled product and panels. Coil free and clear of ice. Fans working. Compressor running. Condenser fan running and clear of dust and debris. Solenoid operational. Superheat ok. Dixell controller working. Correct amount of defrost and defrost time set. Changed high temp alarm from 47° to 65°. Job complete
D32: 46195.463 | F32: Completed | G32: 46195 | H32: WO-0596795 | I32: Southern | J32: Dollar General #20100 | K32: Paulina | L32: LA | M32: TAVANT/PRODUCT CARE | N32: STORE CONNECT | O32: TEMPERATURE | S32: RMN4MA / MY26E039404 | U32: High Temperature alarm | V32: On arrival case was not temping high, checked airflow and confirmed it was good, checked condensing unit and cleaned the small layer of dust I noticed. Also tensioned doors after noticing they do not close by themselves after opening.
D33: 46192.471 | E33: Scheduled for 6/26 return (DG Manager requested return to check on it) | F33: Return Needed | H33: WO-0595748 | I33: Phoenix, AZ | J33: Dollar General #22286 | K33: Arizona City | L33: AZ | M33: 5123730 | N33: FEXA | S33: RLN2MA /MY26B014938 | U33: Not Working at All - Temp is failing, Ice Cream Melting, Product Damaged | V33: Arrived at store checked in with manager checked 2dr freezer and case was running at -6°F talked to manager amd he dont like how temp spikes up 6-8°af after opening door for 10-15 sec case dropps to temp after door closes. Called tech support and spoke with Erik we went through all perameters and chexked temp graph we did find the case is going into 2 defroat back to back. Erik ssaid it ahould be a program issue and that they coulsld do the changes remotely. Case was running at -7° when i left store.
D34: 46191.436 | F34: Completed | G34: 46192 | H34: WO-0594944 | I34: Phoenix, AZ | J34: Dollar General #22286 | K34: Arizona City | L34: AZ | M34: 5125380 | N34: FEXA | O34: TEMPERATURE | S34: RMN5MA/MY26B016552 | U34: High temperature alarm | V34: 6/19 Arrived at store checked in with manager looked for case mentioned on work summary RMN5MA MY26B016552 and there is no case in store with this model# and serial#. Store did have a issue with a 2dr freezer manager said case was to warm during defrost and temp got upto 48°F and took a long time to drop. Case was running at -9°F when i arrived. Checked defrost perameters and found it was programmed for defroat interval of 6hrs changed that to every 8hrs also found max defrost duration set to 60 min changed that to 25 min also end defrost temp was set to 45° changed that to 36°F after making changes ran system throu a defrost cycle ansd monitored case temp did not go higher then 36°F and after defrost case dropped temp case is running at -5°F when i left store. No other issues present at time of departure Arrived onsite 06/18/26, checked in with manager on duty. Gained access to case model # RMNAMA serial # MY26B014985. Found temp at 41°. Manager stated that the door had been left open all night because door wouldn't close on its own. Adjusted door to close on its own. Allowed to cool down. Temp dropped to 37° and stalled. Removed inside rop panel to expose evaporator and fans. Fans are operational and there is no ice visible on coils. Reassembled and forced defrost incase there is any ice i couldn't see. Allowed to complete defrost. Refrigeration restarted. Case began to pull down to 35.7, until case attached satisfied. Then temp went up to 36°. Will return for further diagnosis.
D35: 46191.278 | F35: Completed | G35: 46192 | H35: WO-0594225 | I35: Tulsa, OK | J35: Dollar General #14386 | K35: Norman | L35: OK | M35: TAVANT/PRODUCT CARE | N35: STORE CONNECT | O35: TEMPERATURE | S35: RLN2MA MY26B016452 | U35: High temperature alarm | V35: arrived onsite and assited tech in the removal of faulty micro block and installation on new all checks good Found unit temp at 58°f pull refrigerant out pulled vacuum and recharged 100g of r290 unit still not cooling properly called tech support on unit and they will send new unit to replace this one Returned to install new unit watched temp drop new unit working properly and re addressed to communicate with sc pulse
D36: 46191.089 | E36: Tech was onsite 6/18 per his notes he must return | F36: Return Needed | H36: WO-0594191 | I36: Southern | J36: Dollar General # 13070 | K36: Laurel | L36: MS | M36: TAVANT/PRODUCT CARE | N36: STORE CONNECT | O36: TEMPERATURE | S36: RMN4MA/MY26B014986 | U36: High temperature alarm
D37: 46189.152 | F37: Completed | G37: 46189 | H37: WO-0593126 | I37: Phoenix, AZ | J37: Dollar General #22286 | K37: Arizona City | L37: AZ | M37: 5108840 | N37: FEXA | O37: TEMPERATURE | S37: RLN2MA MY26B014938 | U37: Ice Cream is melting | V37: Checked in with management upon arrival. Found unit down to temp at -6.0, pulled top panel to inspect the EVAP. It had no ice build up. Inspected the controller parameters. Found it has a defrost pre set of 45 min with a temp termination of 45F (7.2C), lowered the time to 20 min and 37F (2.7C). Put unit back together. Ran through a defrost cycle to verify. No further issues found. Unit temped -2 F before departure.
D38: 46189.097 | F38: Completed | G38: 46189 | H38: WO-0592610 | I38: San Antonio, TX | J38: Dollar General #20761 | K38: Pettus | L38: TX | M38: TAVANT/PRODUCT CARE | N38: STORE CONNECT | O38: TEMPERATURE | S38: RLN2MA MY26B013813 | U38: High Temperature alarm | V38: I confirned unit was above temp at approx 16⁰F upon arrival. I verified controller, compressor and both condenser (1) and evaporator (2) fans were function. I confirmed coils were iced up. Checked with Hussmann to confirm theory of operation. I believe a power issue might have caused some controller issue because after a reset the defrost intiated (hot gas) without issue. I maually cleaned coil. I also sealed cracks/opening in the semas of the block. Issue is resolved.
D39: 46188.451 | F39: Completed | G39: 46196 | H39: WO-0592045 | I39: Tulsa, OK | J39: Dollar General #23988 | K39: Kingfisher | L39: OK | M39: TAVANT/PRODUCT CARE/5110636 | N39: STORE CONNECT/FEXA | O39: TEMPERATURE | S39: RLN2MA MY26C025304 | U39: High temperature alarm | V39: 6/23 arrived onsite and replaed hot gas solenoid coil, ran coil thru factory wire casing, turned case, waistedf for case to get to decent temp for system to allow me to put through defrost and test solenoid, ran defrost solenoid worked, made sure temp got down to temp all checks good 6/16 arrived onsite foumd case evaporator iced up, after troubleshooting found hot gas solenoid coil not working has power but not energizing, case still under warranty, spoke to shane he will be filling out and providing the form for performance parts warranty, turned off case will return once part arrived to fix and turn on
D40: 46188.447 | F40: Completed | G40: 46188 | H40: WO-0592039 | I40: Houston, TX | J40: Dollar General #20107 | K40: Baytown | L40: TX | M40: TAVANT/PRODUCT CARE | N40: STORE CONNECT | O40: TEMPERATURE | S40: RMN3MA MY26C025312 | U40: High temperature alarm | V40: 06-15-26 juan olvera technician dispatch send me one service call for the deer and milk case midel RMN3MA, serial number MY26C025312, first i drove to site job upon arrival check-in with manager, for next i found the case and set up the ladder to check the cases compressor, the case is working, i check the airflow, the coil, case temperature, compressors, and the door, i did not found anything wrong the case is working at 34 Fahrenheit, the defrost is working, condenser fan is working during refrigeration mode, for last i submit pictures in document and I explain to the manager my performance further more this call is complete.
D41: 46186.342 | F41: Completed | G41: 46186 | H41: WO-0590801 | I41: Phoenix, AZ | J41: Dollar General #13396 | K41: Coolidge | L41: AZ | M41: TAVANT/PRODUCT CARE | N41: STORE CONNECT | O41: TEMPERATURE | S41: RLN2MA/MY26B016003 | T41: X | U41: High Temperature alarm on cases | V41: Arrived at store checked in with manager checked microblock high temp alarm. After troubleshooting found a 2dr freezer microblock running at 10°F. Ran system through a defrost cycle and cleared out all frost that was on evaperator. Monitored unit after defrost. I did notice condenser temp was running arounf 140°F the store has no AC the are using portable ac units and store is really warm. Removed the trim covering condenser and condenser temp dropped to 129°F and temp inside case started to drop a little faster. Case is dropping case got down to 4°F but customers keep openning the doors and temps goes right up.
...

Sheet Settings
A1: Root Cause Settings - dropdown source and clean-point rules
A3: Root Cause | B3: Group | C3: Owner | D3: Status | E3: Clean-Point Date | F3: Clean-Point Serial | G3: Display Order | H3: Cause Color (hex) | I3: Group Color (hex)
A4: Ref. leak/ Low charge | B4: Ref. leak/ Low charge | C4: Tecumseh | D4: Closed | E4: 46132 | G4: 1 | H4: 70AD47 | I4: 70AD47
A5: Door Torque | B5: Doors | C5: Hussmann MTY | D5: Closed | E5: 46178 | G5: 2 | H5: FFC000 | I5: FFC000
A6: Door Gasket | B6: Doors | C6: HSM MTY/RPM | D6: Closed | E6: 46178 | F6: NA | G6: 3 | H6: FFC000 | I6: FFC000
A7: Door frame heater | B7: Doors | C7: HSM MTY | D7: Closed | E7: 46178 | F7: NA | G7: 4 | H7: FFC000 | I7: FFC000
A8: Door Torsion rod | B8: Doors | C8: HSM MTY/RPM | D8: Closed | E8: 46178 | F8: NA | G8: 5 | H8: FFC000 | I8: FFC000
A9: Door not closed (Overnight) | B9: Doors | C9: HSM MTY/ RPM | D9: Closed | E9: 46178 | G9: 6 | H9: FFC000 | I9: FFC000
